Workbook

Sheet DSKH
C1: CÔNG TY TNHH VẬN TẢI ĐẠI LỘ XANH
C2: MST : 2500774911
C3: Địa chỉ : Số nhà 306, đường 303, thôn Giã Bàng, Xã Tề Lỗ, Tỉnh Phú Thọ, Việt Nam
A6: Số HĐ | C6: MST | D6: Tên khách hàng | E6: Địa chỉ | F6: Người đại diện | G6: Chức vụ | H6: STK 1 | I6: Ngân hàng 1 | J6: STK 2 | K6: Ngân hàng 2
A7: {=_xlfn.UNIQUE(Table1[Số HĐ]:Table1[Số HĐ])} -> 1 | C7: 0101439643 | D7: CÔNG TY TNHH ỨNG DỤNG GIẢI PHÁP CÔNG NGHỆ | E7: Số 100 Ngõ 40 Tạ Quang Bửu, Phường Bạch Mai, Thành phố Hà Nội, Việt Nam | F7: NINH ĐỨC CƯỜNG | G7: Giám đốc | H7: 21100164008 | I7: Tại ngân hàng TMCP Quân Đội - Mbbank
A8: 2 | C8: 0106654549 | D8: CÔNG TY TNHH THIẾT BỊ ĐO LƯỜNG VÀ GIẢI PHÁP CÔNG NGHỆ TRƯỜNG PHÁT | E8: Lô 27, Khu A1A2A3, Tổ 7, Phường Long Biên, Thành phố Hà Nội, Việt Nam | F8: NGUYỄN THẾ DUYÊN | G8: Giám đốc | H8: 995 6868 668 668 | I8: Tại ngân hàng MBBank - CN Long Biên, Hà Nội
A9: 3 | C9: 0109796541 | D9: CÔNG TY TNHH TƯ VẤN KIỂM ĐỊNH VÀ THIẾT BỊ ĐO LƯỜNG | E9: Số 24 Liền kề 4, KĐT Đại Thanh, Xã Đại Thanh, Thành phố Hà Nội, Việt Nam | F9: LÊ DUY PHƯƠNG | G9: Giám đốc | H9: 111333666666 | I9: Tại ngân hàng ACB - CN Linh Đàm
A10: 4 | C10: 0107083249 | D10: CÔNG TY CỎ PHẦN DỊCH VỤ TƯ VẤN VÀ KIỂM ĐỊNH VIỆT NAM | E10: Số 84, phố Ngọc Trì, Tổ 7, Phường Long Biên, Thành phố Hà Nội, Việt Nam | F10: NGUYỄN ANH TIẾN | G10: Giám đốc | H10: 996688886666 | I10: Tại ngân hàng MBBank - CN Trần Hưng Đạo | J10: 2103236688 | K10: Tại ngân hàng Techcombank - CN Chương Dương
A11: 5 | C11: 4601654519 | D11: CÔNG TY TNHH KHOA HỌC DỊCH VỤ KỸ THUẬT TÂN THỊNH PHÁT | E11: Số nhà 37, Tổ 11, Phường Tích Lương, Tỉnh Thái Nguyên, Việt Nam | F11: NÔNG VĂN VIỆT | G11: Giám đốc | H11: 116602850666 | I11: Tại ngân hàng VIETINBANK - CN Thái Nguyên
A12: 6 | C12: 2500675251 | D12: CÔNG TY TNHH GIẢI PHÁP CÔNG NGHỆ VINACO VIỆT NAM | E12: Thôn Vân Nội, Xã Hội Thịnh, Tỉnh Phú Thọ, Việt Nam | F12: LÊ VĂN LĂNG | G12: Giám đốc | H12: 119602319999 | I12: Tại ngân hàng VIETINBANK - CN Bình Xuyên
A13: 7 | C13: 0102169887 | D13: CÔNG TY TNHH MÔI TRƯỜNG CÔNG NGHIỆP XANH | E13: Tổ Xuân Mai 1, Phường Phúc Yên, Tỉnh Phú Thọ, Việt Nam
A14: 8 | C14: 2500708852 | D14: CÔNG TY CỔ PHẦN TECON88 | E14: Số 59 Đường Quang Trung, Phố Tiên, Phường Vĩnh Yên, Tỉnh Phú Thọ, Việt Nam
A15: 9 | C15: 0107019878 | D15: CÔNG TY CỔ PHẦN XÂY DỰNG HẠ TẦNG THỊNH PHÁT | E15: Thôn Phú Mỹ, xã Chương Dương, TP. Hà Nội, Việt Nam | F15: DƯƠNG VĂN DUÂN | G15: Giám đốc | H15: 89084075 | I15: Tại Ngân hàng VP Bank- Chi nhánh Ngô Quyền – PGD Thái Hà, Hà Nội
A16: 10 | C16: 2500598864 | D16: CÔNG TY TNHH CÂN ĐIỆN TỬ THẾ HỆ MỚI | E16: Thôn Đồng Lực, Xã Hoàng An, Tỉnh Phú Thọ, Việt Nam | F16: LƯU VĂN HÙNG | G16: Giám đốc | H16: 112002651186 | I16: Tại ngân hàng VIETINBANK - CN Vĩnh Phúc
A17: 11 | C17: 2500518379 | D17: CÔNG TY CỔ PHẦN CÂN ĐIỆN TỬ VĨNH PHÚC | E17: Khu Lai Sơn, Phường Vĩnh Yên, Tỉnh Phú Thọ, Việt Nam | F17: NGUYỄN TUẤN HƯỞNG | G17: Giám đốc | H17: 1017686777 | I17: Tại ngân hàng TMCP Công thương Việt Nam
A18: 12 | C18: 2600706055 | D18: TRUNG TÂM KỸ THUẬT TIÊU CHUẨN ĐO LƯỜNG CHẤT LƯỢNG | E18: Đường Kim Đồng, Phường Việt Trì, T. Phú Thọ | F18: NGUYỄN HỮU HÀ | G18: Giám đốc | H18: 118000066436 | I18: Tại ngân hàng TMCP Công thương Việt Nam - CN Hùng Vương
A19: 13 | C19: 2500763469 | D19: CÔNG TY TNHH CÁT SỎI THUỶ MỘC PHÁT | E19: Thôn Nội, Xã Vĩnh An, Tỉnh Phú Thọ, Việt Nam
A20: 14 | C20: 0401886963 | D20: CÔNG TY TNHH MTV CÔNG NGHỆ ĐO LƯỜNG - ĐIỀU KHIỂN VŨ DUY | E20: K428 Tôn Đản, Phường An Khê, Thành phố Đà Nẵng, Việt Nam
A21: 15 | C21: 2500603377 | D21: CÔNG TY CỔ PHẦN KIỂM ĐỊNH MKV | E21: Đường Phạm Đình Hổ, Phường Vĩnh Yên, Tỉnh Phú Thọ, Việt Nam | F21: VŨ THỊ HIẾN | G21: Giám đốc | H21: 3201010686836 | I21: Tại ngân hàng TMCP Hàng Hải Việt Nam
A22: 16 | C22: 2300226957 | D22: CÔNG TY TNHH HƯƠNG GIA VỊ SƠN HÀ | E22: Phố Quế, Cụm Công nghiệp Đa nghề Đình Bảng, Phường Từ Sơn, Tỉnh Bắc Ninh, Việt Nam
A23: 17 | C23: 0105436996 | D23: CÔNG TY TNHH SẢN XUẤT CÔNG NGHỆ TÂN NAM PHÁT | E23: Số 45B2 ngõ 649 đường Lĩnh Nam, Phường Vĩnh Hưng, Thành phố Hà Nội
A24: 18 | C24: 0109205534 | D24: CÔNG TY TNHH TM VÀ DỊCH VỤ TỰ ĐỘNG HÓA THÀNH CÔNG | E24: Thửa đất số 171CBĐ 03, Tổ 5 Phường Yên Nghĩa, Thành Phố Hà Nội | F24: LÊ THỊ DINH | G24: Giám đốc | H24: 5566338888 | I24: Tại ngân hàng TMCP Á Châu – CN Hà Nội
A25: 19 | C25: 2500561310 | D25: CÔNG TY TNHH MỘT THÀNH VIÊN CÂN ĐIỆN TỬ VĨNH PHÚC | E25: Số nhà 25, Tổ dân phố Đậu, Phường Vĩnh Phúc, Tỉnh Phú Thọ, Việt Nam
A26: 20 | C26: 0107705669 | D26: CÔNG TY TNHH THIẾT BỊ ĐO LƯỜNG VÀ CÔNG NGHIỆP 247 | E26: Số 5, Ngõ 254, Đường Mỹ Đình, Phường Từ Liêm, Thành phố Hà Nội, Việt Nam | F26: HÀ HỮU TIẾN | G26: Giám đốc | H26: 686868247247 | I26: Tại ngân hàng TMCP Quân Đội - Mbbank
A27: 21 | C27: 2500649903 | D27: CÔNG TY TNHH H2Y VINA | E27: Khu đô thị Đồng Sơn, tổ 9, Phường Phúc Yên, Tỉnh Phú Thọ, Việt Nam
A28: 22 | C28: 2500449799 | D28: CÔNG TY TNHH CÔNG NGHỆ VÀ DỊCH VỤ VIETLIFE | E28: Số nhà 04, Ngõ 04, Phố Chiền, Phường Vĩnh Phúc, Tỉnh Phú Thọ, Việt Nam | F28: NGUYỄN THỊ THU TRANG | G28: Giám đốc | H28: 2800201007019 | I28: Tại ngân hàng NN và PTNT Việt Nam
A29: 23 | C29: 0106342099 | D29: CÔNG TY TNHH ĐO LƯỜNG, ĐIỀU KHIỂN VÀ GIÁM SÁT THÁI BÌNH | E29: Số 55, Ngõ 89, phố Bùi Huy Bích, Phường Hoàng Mai, Thành phố Hà Nội, Việt Nam
A30: 24 | C30: 2500424145 | D30: CÔNG TY TNHH THIẾT BỊ CÔNG NGHIỆP HTC VĨNH PHÚC | E30: Ngõ 07, Đường Lý Thường Kiệt, TDP Lai Sơn, Phường Vĩnh Yên, Tỉnh Phú Thọ | F30: NGUYỄN VĂN THIẾT | G30: Giám đốc | H30: 361000307212 | I30: Tại ngân hàng TMCP Công thương Việt Nam | J30: 4250338600 | K30: Tại Ngân Hàng BIDV – CN Vĩnh Phúc
A31: 25 | C31: 4601506704 | D31: CÔNG TY TNHH SẢN XUẤT VÁN ÉP THÀNH PHÚ | E31: Xóm Tân Lập, Phường Phúc Thuận, Tỉnh Thái Nguyên, Việt Nam | F31: NGUYỄN THỊ TUYẾT | G31: Giám đốc | H31: 020063698866 | I31: Tại ngân hàng Sacombank – CN Long Biên Hà Nội
A32: 26 | C32: 1101925902 | D32: CÔNG TY TNHH KỸ THUẬT ĐO LƯỜNG TÂN QUỐC HƯNG | E32: Lô M-3, Đường Trung Tâm, Khu Công Nghiệp Long Hậu Mở Rộng, Ấp Long Hậu 3, Xã Cần Giuộc, Tỉnh Tây Ninh, Việt Nam
A33: 27 | C33: 2500779878 | D33: CÔNG TY TNHH ĐẦU TƯ PHÁT TRIỂN THƯƠNG MẠI THÀNH TIẾN | E33: Thôn Đại Định, Xã Vĩnh Thành, Tỉnh Phú Thọ, Việt Nam | F33: LÊ HÀ TUYÊN | G33: Giám đốc | H33: 296333999 | I33: Tại ngân hàng MBBANK
A34: 28 | C34: 4601294471 | D34: CÔNG TY TNHH KHOA HỌC VÀ KỸ THUẬT KTC THÁI NGUYÊN | E34: Tổ 1, Phường Quyết Thắng, Tỉnh Thái Nguyên, Việt Nam
A35: 29 | C35: 2500632681 | D35: CÔNG TY CỔ PHẦN VINOTA | E35: Số nhà 169-171 Hàng Bông, Phường Hoàn Kiếm, Thành phố Hà Nội, Việt Nam
A36: 30 | C36: 2601079689 | D36: CÔNG TY TNHH KĨ THUẬT VÀ THƯƠNG MẠI NTD | E36: Tổ 4B, Khu Hương Trầm, Phường Việt Trì, Tỉnh Phú Thọ, Việt Nam
A37: 31 | C37: 2300779937 | D37: CÔNG TY CỔ PHẦN NGÔI SAO KINH BẮC | E37: Khu Quán Trắng, Phường Tiên Du, Thành phố Bắc Ninh, Việt Nam
A38: 32 | C38: 0109163588 | D38: CÔNG TY TNHH THIẾT BỊ ĐO LƯỜNG ĐỨC PHÚC | E38: Phòng 302, Nhà số 8, Ngõ 31 Phố Phương Liệt, Phường Phương Liệt, TP Hà Nội, Việt Nam
A39: 33
A40: 34
A41: 35
A42: 36
...

Sheet Hợp đồng 
A1: CỘNG HÒA XÃ HỘI CHỦ NGHĨA VIỆT NAM | S1: ngày | T1: 22
A2: Độc lập - Tự do - Hạnh phúc | S2: tháng | T2: 06
A3: ----------o0o---------- | S3: năm 2026
A5: HỢP ĐỒNG VẬN CHUYỂN | S5: MST : | T5: 2500449799
A6: ="Số :"&" "&T1&T2&"26/"&"HĐNT/"&T6&"-ĐLX" -> Số : 220626/HĐNT/VIETLIFE-ĐLX | T6: VIETLIFE
A8: - Căn cứ vào luật thương mại có hiệu lực ngày 01/01/2006.
A9: - Căn cứ vào bộ luật dân sự có hiệu lực ngày 01/01/2006.
A10: - Căn cứ vào hướng dẫn HD 1889/TTG ngày 19 tháng 12 năm 2005 hướng dẫn lập hợp đồng
A11: kinh tế.
A12: - Căn cứ vào nhu cầu và khả năng của hai bên.
A13: Hôm nay, | B13: ="ngày"&" "&T1&" "&"tháng"&" "&T2&" "&S3 -> ngày 22 tháng 06 năm 2026 | J13: ,tại văn phòng CÔNG TY TNHH VẬN TẢI ĐẠI LỘ
A14: XANH, chúng tôi đại diện cho các bên tham gia ký kết hợp đồng gồm:
A15: Bên thuê vận chuyển(Bên A): | F15: =_xlfn.IFNA(VLOOKUP($T$5,Table2[#All],2,0),"") -> CÔNG TY TNHH CÔNG NGHỆ VÀ DỊCH VỤ VIETLIFE
A16: Đại diện | B16: Bà | C16: =_xlfn.IFNA(VLOOKUP($T$5,Table2[#All],4,0),"") -> NGUYỄN THỊ THU TRANG | M16: Chức vụ: | N16: =_xlfn.IFNA(VLOOKUP($T$5,Table2[#All],5,0),"") -> Giám đốc
A17: Địa chỉ | B17: =_xlfn.IFNA(VLOOKUP($T$5,Table2[#All],3,0),"") -> Số nhà 04, Ngõ 04, Phố Chiền, Phường Vĩnh Phúc, Tỉnh Phú Thọ, Việt Nam
A18: Điện thoại
A19: Mã số thuế | B19: =_xlfn.IFNA(VLOOKUP($T$5,Table2[#All],1,0),"") -> 2500449799
A20: Tài khoản | B20: =_xlfn.IFNA(VLOOKUP($T$5,Table2[#All],6,0),"") -> 2800201007019 | M20: =_xlfn.IFNA(VLOOKUP($T$5,Table2[#All],7,0),"") -> Tại ngân hàng NN và PTNT Việt Nam
B21: =_xlfn.IFNA(VLOOKUP($T$5,Table2[#All],8,0),"") -> 0 | M21: =_xlfn.IFNA(VLOOKUP($T$5,Table2[#All],9,0),"") -> 0
A23: Bên vận chuyển(Bên B): | E23: CÔNG TY TNHH VẬN TẢI ĐẠI LỘ XANH
A24: Đại diện | B24: Ông | C24: NGUYỄN KIM QUYẾT | M24: Chức vụ : | N24: Giám đốc
A25: Địa chỉ | B25: Số nhà 306, đường 303, thôn Giã Bàng, Xã Tề Lỗ, Tỉnh Phú Thọ, Việt Nam
A26: Điện thoại | B26: 912559868
A27: Mã số thuế | B27: 2500774911
A28: Tài khoản | B28: 110003058298 | M28: Tại ngân hàng VIETINBANK - PGD Bắc Yên Lạc
A29: Email | B29: vantaidailoxanh2026@gmail.com
A31: Sau khi thương thảo, bàn bạc, hai bên thống nhất ký kết hợp đồng vận chuyển với các điều
A32: khoản sau:
A33: NỘI DUNG CÔNG VIỆC GIAO DỊCH :
A34: Điều 1: NỘI DUNG CỦA HỢP ĐỒNG
A35: Bên A thuê vận chuyển và Bên B nhận cung cấp, điều động phương tiện để vận chuyển hàng hóa theo
A36: yêu cầu của Bên A như sau :
A37: - Tên hàng hóa : | C37: bàn cân, quả chuẩn hoặc các mặt hàng do bên thuê vận chuyển yêu cầu.
A38: - Đơn vị tính : | C38: chuyến
A39: - Số lượng : | C39: Theo thông báo từng chuyến/đợt.
A40: - Cự ly vận chuyển : | D40: Căn cứ theo thỏa thuận của từng lô hàng.
A42: Điều 2: ĐƠN GIÁ, KHỐI LƯỢNG, ĐỊA ĐIỂM GIAO NHẬN HÀNG HÓA
A43: 2.1. Đơn giá áp dụng theo chuyến do hai bên thỏa thuận theo từng thời điểm.
A44: 2.2. Khối lượng hàng hoá chở tối thiểu trên một chuyến theo định mức của bên vận chuyển.
A45: 2.3 Địa điểm giao nhận hàng hóa cụ thể từng chuyến sẽ thông báo theo yêu cầu của bên A.
...

Sheet DATA
A1: CÔNG TY TNHH VẬN TẢI ĐẠI LỘ XANH
A2: MST : 2500774911
A3: Địa chỉ : Số nhà 306, đường 303, thôn Giã Bàng, Xã Tề Lỗ, Tỉnh Phú Thọ, Việt Nam
A4: BSX : | B4: 19H-147.98
A7: Đếm | B7: Số HĐ | C7: Ngày tháng | D7: MST | E7: Tên đơn vị | F7: Địa chỉ | G7: Tên hàng hóa ,dịch vụ | H7: ĐVT | I7: Số lượng | J7: Đơn giá | K7: Thành tiền
A8: =IF(Table1[[#This Row],[Số HĐ]]=BBVC!$R$2,MAX(DATA!A7:A7)+1,"") | B8: 1 | C8: 46162 | D8: 0101439643 | E8: =VLOOKUP(Table1[[#This Row],[MST]],Table2[#All],2,0) -> CÔNG TY TNHH ỨNG DỤNG GIẢI PHÁP CÔNG NGHỆ | F8: =VLOOKUP(Table1[[#This Row],[MST]],Table2[#All],3,0) -> Số 100 Ngõ 40 Tạ Quang Bửu, Phường Bạch Mai, Thành phố Hà Nội, Việt Nam | G8: Cước cẩu vận chuyển bàn cân 18mx3m và quả chuẩn từ Bắc Ninh đi Phổ Yên, Thái Nguyên | H8: Chuyến | I8: 1 | J8: 13500000 | K8: =Table1[[#This Row],[Số lượng]]*Table1[[#This Row],[Đơn giá]] -> 13500000
A9: =IF(Table1[[#This Row],[Số HĐ]]=BBVC!$R$2,MAX(DATA!A8:A8)+1,"") | B9: 2 | C9: 46162 | D9: 0106654549 | E9: =VLOOKUP(Table1[[#This Row],[MST]],Table2[#All],2,0) -> CÔNG TY TNHH THIẾT BỊ ĐO LƯỜNG VÀ GIẢI PHÁP CÔNG NGHỆ TRƯỜNG PHÁT | F9: =VLOOKUP(Table1[[#This Row],[MST]],Table2[#All],3,0) -> Lô 27, Khu A1A2A3, Tổ 7, Phường Long Biên, Thành phố Hà Nội, Việt Nam | G9: Cước vận chuyển quả cân từ Tề Lỗ, Phú Thọ đi KCN Thăng Long- Hưng Yên | H9: Chuyến | I9: 1 | J9: 7000000 | K9: =Table1[[#This Row],[Số lượng]]*Table1[[#This Row],[Đơn giá]] -> 7000000
A10: =IF(Table1[[#This Row],[Số HĐ]]=BBVC!$R$2,MAX(DATA!A9:A9)+1,"") | B10: 3 | C10: 46162 | D10: 0106654549 | E10: =VLOOKUP(Table1[[#This Row],[MST]],Table2[#All],2,0) -> CÔNG TY TNHH THIẾT BỊ ĐO LƯỜNG VÀ GIẢI PHÁP CÔNG NGHỆ TRƯỜNG PHÁT | F10: =VLOOKUP(Table1[[#This Row],[MST]],Table2[#All],3,0) -> Lô 27, Khu A1A2A3, Tổ 7, Phường Long Biên, Thành phố Hà Nội, Việt Nam | G10: Cước vận chuyển bàn cân từ Vĩnh Yên, Phú Thọ đi Gia Bình, Bắc Ninh | H10: Chuyến | I10: 1 | J10: 7500000 | K10: =Table1[[#This Row],[Số lượng]]*Table1[[#This Row],[Đơn giá]] -> 7500000
A11: =IF(Table1[[#This Row],[Số HĐ]]=BBVC!$R$2,MAX(DATA!A10:A10)+1,"") | B11: 4 | C11: 46164 | D11: 0109796541 | E11: =VLOOKUP(Table1[[#This Row],[MST]],Table2[#All],2,0) -> CÔNG TY TNHH TƯ VẤN KIỂM ĐỊNH VÀ THIẾT BỊ ĐO LƯỜNG | F11: =VLOOKUP(Table1[[#This Row],[MST]],Table2[#All],3,0) -> Số 24 Liền kề 4, KĐT Đại Thanh, Xã Đại Thanh, Thành phố Hà Nội, Việt Nam | G11: Cước vận chuyển quả cân từ Tề Lỗ, Phú Thọ đi KCN Quang Minh, Hà Nội | H11: Chuyến | I11: 1 | J11: 2000000 | K11: =Table1[[#This Row],[Số lượng]]*Table1[[#This Row],[Đơn giá]] -> 2000000
A12: =IF(Table1[[#This Row],[Số HĐ]]=BBVC!$R$2,MAX(DATA!A11:A11)+1,"") | B12: 5 | C12: 46164 | D12: 4601654519 | E12: =VLOOKUP(Table1[[#This Row],[MST]],Table2[#All],2,0) -> CÔNG TY TNHH KHOA HỌC DỊCH VỤ KỸ THUẬT TÂN THỊNH PHÁT | F12: =VLOOKUP(Table1[[#This Row],[MST]],Table2[#All],3,0) -> Số nhà 37, Tổ 11, Phường Tích Lương, Tỉnh Thái Nguyên, Việt Nam | G12: Cước vận chuyển bàn cân từ Công ty Cổ Phần Tuệ An đến Cụm Công Nghiệp Thắng Quân, Tuyên Quang | H12: Chuyến | I12: 1 | J12: 12000000 | K12: =Table1[[#This Row],[Số lượng]]*Table1[[#This Row],[Đơn giá]] -> 12000000
A13: =IF(Table1[[#This Row],[Số HĐ]]=BBVC!$R$2,MAX(DATA!A12:A12)+1,"") | B13: 6 | C13: 46164 | D13: 0107083249 | E13: =VLOOKUP(Table1[[#This Row],[MST]],Table2[#All],2,0) -> CÔNG TY CỎ PHẦN DỊCH VỤ TƯ VẤN VÀ KIỂM ĐỊNH VIỆT NAM | F13: =VLOOKUP(Table1[[#This Row],[MST]],Table2[#All],3,0) -> Số 84, phố Ngọc Trì, Tổ 7, Phường Long Biên, Thành phố Hà Nội, Việt Nam | G13: Cước vận chuyển quả cân từ Tề Lỗ, Phú Thọ đi KCN Thụy Vân, Phú Thọ | H13: Chuyến | I13: 1 | J13: 6500000 | K13: =Table1[[#This Row],[Số lượng]]*Table1[[#This Row],[Đơn giá]] -> 6500000
A14: =IF(Table1[[#This Row],[Số HĐ]]=BBVC!$R$2,MAX(DATA!A13:A13)+1,"") | B14: 7 | C14: 46165 | D14: 2500675251 | E14: =VLOOKUP(Table1[[#This Row],[MST]],Table2[#All],2,0) -> CÔNG TY TNHH GIẢI PHÁP CÔNG NGHỆ VINACO VIỆT NAM | F14: =VLOOKUP(Table1[[#This Row],[MST]],Table2[#All],3,0) -> Thôn Vân Nội, Xã Hội Thịnh, Tỉnh Phú Thọ, Việt Nam | G14: Cước vận chuyển cân đóng bao từ Phú Thọ đi Hưng Yên | H14: Chuyến | I14: 1 | J14: 6000000 | K14: =Table1[[#This Row],[Số lượng]]*Table1[[#This Row],[Đơn giá]] -> 6000000
A15: =IF(Table1[[#This Row],[Số HĐ]]=BBVC!$R$2,MAX(DATA!A14:A14)+1,"") | B15: 8 | C15: 46165 | D15: 0109796541 | E15: =VLOOKUP(Table1[[#This Row],[MST]],Table2[#All],2,0) -> CÔNG TY TNHH TƯ VẤN KIỂM ĐỊNH VÀ THIẾT BỊ ĐO LƯỜNG | F15: =VLOOKUP(Table1[[#This Row],[MST]],Table2[#All],3,0) -> Số 24 Liền kề 4, KĐT Đại Thanh, Xã Đại Thanh, Thành phố Hà Nội, Việt Nam | G15: Cước vận chuyển quả cân từ Tề Lỗ, Phú Thọ đi Suối Hai, Hà Nội | H15: Chuyến | I15: 1 | J15: 4000000 | K15: =Table1[[#This Row],[Số lượng]]*Table1[[#This Row],[Đơn giá]] -> 4000000
A16: =IF(Table1[[#This Row],[Số HĐ]]=BBVC!$R$2,MAX(DATA!A15:A15)+1,"") | B16: 9 | C16: 46165 | D16: 0102169887 | E16: =VLOOKUP(Table1[[#This Row],[MST]],Table2[#All],2,0) -> CÔNG TY TNHH MÔI TRƯỜNG CÔNG NGHIỆP XANH | F16: =VLOOKUP(Table1[[#This Row],[MST]],Table2[#All],3,0) -> Tổ Xuân Mai 1, Phường Phúc Yên, Tỉnh Phú Thọ, Việt Nam | G16: Cước vận chuyển quả cân từ Phường Vĩnh Phúc đi Phúc Yên, Phú Thọ | H16: Chuyến | I16: 1 | J16: 3500000 | K16: =Table1[[#This Row],[Số lượng]]*Table1[[#This Row],[Đơn giá]] -> 3500000
A17: =IF(Table1[[#This Row],[Số HĐ]]=BBVC!$R$2,MAX(DATA!A16:A16)+1,"") -> 1 | B17: 10 | C17: 46165 | D17: 2500708852 | E17: =VLOOKUP(Table1[[#This Row],[MST]],Table2[#All],2,0) -> CÔNG TY CỔ PHẦN TECON88 | F17: =VLOOKUP(Table1[[#This Row],[MST]],Table2[#All],3,0) -> Số 59 Đường Quang Trung, Phố Tiên, Phường Vĩnh Yên, Tỉnh Phú Thọ, Việt Nam | G17: Cước vận chuyển thép hình từ Tề Lỗ, Phú Thọ đến Phường Vĩnh Yên, Phú Thọ | H17: Chuyến | I17: 1 | J17: 2000000 | K17: =Table1[[#This Row],[Số lượng]]*Table1[[#This Row],[Đơn giá]] -> 2000000
A18: =IF(Table1[[#This Row],[Số HĐ]]=BBVC!$R$2,MAX(DATA!A17:A17)+1,"") | B18: 11 | C18: 46166 | D18: 2500675251 | E18: =VLOOKUP(Table1[[#This Row],[MST]],Table2[#All],2,0) -> CÔNG TY TNHH GIẢI PHÁP CÔNG NGHỆ VINACO VIỆT NAM | F18: =VLOOKUP(Table1[[#This Row],[MST]],Table2[#All],3,0) -> Thôn Vân Nội, Xã Hội Thịnh, Tỉnh Phú Thọ, Việt Nam | G18: Cước vận chuyển sắt từ Đông Anh về Công ty TNHH Giải Pháp Công Nghệ Vinaco Việt Nam tại Phú Thọ phục vụ sản xuất | H18: Chuyến | I18: 2 | J18: 3000000 | K18: =Table1[[#This Row],[Số lượng]]*Table1[[#This Row],[Đơn giá]] -> 6000000
A19: =IF(Table1[[#This Row],[Số HĐ]]=BBVC!$R$2,MAX(DATA!A18:A18)+1,"") | B19: 12 | C19: 46167 | D19: 0107019878 | E19: =VLOOKUP(Table1[[#This Row],[MST]],Table2[#All],2,0) -> CÔNG TY CỔ PHẦN XÂY DỰNG HẠ TẦNG THỊNH PHÁT | F19: =VLOOKUP(Table1[[#This Row],[MST]],Table2[#All],3,0) -> Thôn Phú Mỹ, xã Chương Dương, TP. Hà Nội, Việt Nam | G19: Cước vận chuyển container từ Tề Lỗ, Phú Thọ đến Ngọc Hồi, Hà Nội | H19: Chuyến | I19: 1 | J19: 3703704 | K19: =Table1[[#This Row],[Số lượng]]*Table1[[#This Row],[Đơn giá]] -> 3703704
A20: =IF(Table1[[#This Row],[Số HĐ]]=BBVC!$R$2,MAX(DATA!A19:A19)+1,"") | B20: 13 | C20: 46167 | D20: 2500598864 | E20: =VLOOKUP(Table1[[#This Row],[MST]],Table2[#All],2,0) -> CÔNG TY TNHH CÂN ĐIỆN TỬ THẾ HỆ MỚI | F20: =VLOOKUP(Table1[[#This Row],[MST]],Table2[#All],3,0) -> Thôn Đồng Lực, Xã Hoàng An, Tỉnh Phú Thọ, Việt Nam | G20: Cước vận chuyển quả chuẩn từ Xã Tề Lỗ , Phú Thọ đến Xã Kỳ Sơn, Phú Thọ | H20: Chuyến | I20: 1 | J20: 4500000 | K20: =Table1[[#This Row],[Số lượng]]*Table1[[#This Row],[Đơn giá]] -> 4500000
A21: =IF(Table1[[#This Row],[Số HĐ]]=BBVC!$R$2,MAX(DATA!A20:A20)+1,"") | B21: 14 | C21: 46171 | D21: 0101439643 | E21: =VLOOKUP(Table1[[#This Row],[MST]],Table2[#All],2,0) -> CÔNG TY TNHH ỨNG DỤNG GIẢI PHÁP CÔNG NGHỆ | F21: =VLOOKUP(Table1[[#This Row],[MST]],Table2[#All],3,0) -> Số 100 Ngõ 40 Tạ Quang Bửu, Phường Bạch Mai, Thành phố Hà Nội, Việt Nam | G21: Cước vận chuyển bàn cân từ Hội Thịnh, Phú Thọ đến KCN Thuỵ Vân, Phú Thọ | H21: Chuyến | I21: 1 | J21: 7000000 | K21: =Table1[[#This Row],[Số lượng]]*Table1[[#This Row],[Đơn giá]] -> 7000000
A22: =IF(Table1[[#This Row],[Số HĐ]]=BBVC!$R$2,MAX(DATA!A21:A21)+1,"") | B22: 15 | C22: 46171 | D22: 2500518379 | E22: =VLOOKUP(Table1[[#This Row],[MST]],Table2[#All],2,0) -> CÔNG TY CỔ PHẦN CÂN ĐIỆN TỬ VĨNH PHÚC | F22: =VLOOKUP(Table1[[#This Row],[MST]],Table2[#All],3,0) -> Khu Lai Sơn, Phường Vĩnh Yên, Tỉnh Phú Thọ, Việt Nam | G22: Cước vận chuyển bàn cân từ Vĩnh Yên, Phú Thọ đến Hương Khê, Hà Tĩnh | H22: Chuyến | I22: 1 | J22: 24000000 | K22: =Table1[[#This Row],[Số lượng]]*Table1[[#This Row],[Đơn giá]] -> 24000000
A23: =IF(Table1[[#This Row],[Số HĐ]]=BBVC!$R$2,MAX(DATA!A22:A22)+1,"") | B23: 16 | C23: 46171 | D23: 2600706055 | E23: =VLOOKUP(Table1[[#This Row],[MST]],Table2[#All],2,0) -> TRUNG TÂM KỸ THUẬT TIÊU CHUẨN ĐO LƯỜNG CHẤT LƯỢNG | F23: =VLOOKUP(Table1[[#This Row],[MST]],Table2[#All],3,0) -> Đường Kim Đồng, Phường Việt Trì, T. Phú Thọ | G23: Cước vận chuyển chuẩn và trang thiết bị phục vụ kiểm định 04 cân ô tô từ Trung tâm Kỹ thuật tiêu chuẩn đo lường chất lượng (Phú Thọ) đến Tổng công ty giấy Việt Nam và cẩu phục vụ kiểm định | H23: Chuyến | I23: 4 | J23: 5000000 | K23: =Table1[[#This Row],[Số lượng]]*Table1[[#This Row],[Đơn giá]] -> 20000000
A24: =IF(Table1[[#This Row],[Số HĐ]]=BBVC!$R$2,MAX(DATA!A23:A23)+1,"") | B24: 17 | C24: 46172 | D24: 0109796541 | E24: =VLOOKUP(Table1[[#This Row],[MST]],Table2[#All],2,0) -> CÔNG TY TNHH TƯ VẤN KIỂM ĐỊNH VÀ THIẾT BỊ ĐO LƯỜNG | F24: =VLOOKUP(Table1[[#This Row],[MST]],Table2[#All],3,0) -> Số 24 Liền kề 4, KĐT Đại Thanh, Xã Đại Thanh, Thành phố Hà Nội, Việt Nam | G24: Cước vận chuyển quả chuẩn từ Tề Lỗ, Phú Thọ đi KCN Thuận Thành, Bắc Ninh | H24: Chuyến | I24: 1 | J24: 9000000 | K24: =Table1[[#This Row],[Số lượng]]*Table1[[#This Row],[Đơn giá]] -> 9000000
A25: =IF(Table1[[#This Row],[Số HĐ]]=BBVC!$R$2,MAX(DATA!A24:A24)+1,"") | B25: 17 | C25: 46172 | D25: 0109796541 | E25: =VLOOKUP(Table1[[#This Row],[MST]],Table2[#All],2,0) -> CÔNG TY TNHH TƯ VẤN KIỂM ĐỊNH VÀ THIẾT BỊ ĐO LƯỜNG | F25: =VLOOKUP(Table1[[#This Row],[MST]],Table2[#All],3,0) -> Số 24 Liền kề 4, KĐT Đại Thanh, Xã Đại Thanh, Thành phố Hà Nội, Việt Nam | G25: Cước vận chuyển quả chuẩn từ Tề Lỗ, Phú Thọ đi Hà Nội | H25: Chuyến | I25: 1 | J25: 7000000 | K25: =Table1[[#This Row],[Số lượng]]*Table1[[#This Row],[Đơn giá]] -> 7000000
A26: =IF(Table1[[#This Row],[Số HĐ]]=BBVC!$R$2,MAX(DATA!A25:A25)+1,"") | B26: 18 | C26: 46175 | D26: 2500763469 | E26: =VLOOKUP(Table1[[#This Row],[MST]],Table2[#All],2,0) -> CÔNG TY TNHH CÁT SỎI THUỶ MỘC PHÁT | F26: =VLOOKUP(Table1[[#This Row],[MST]],Table2[#All],3,0) -> Thôn Nội, Xã Vĩnh An, Tỉnh Phú Thọ, Việt Nam | G26: Cước vận chuyển bàn cân từ Tề Lỗ, Phú Thọ đến bến cát thôn Đa Cai, Xã Sơn Đông, Tỉnh Phú Thọ | H26: Chuyến | I26: 1 | J26: 4000000 | K26: =Table1[[#This Row],[Số lượng]]*Table1[[#This Row],[Đơn giá]] -> 4000000
A27: =IF(Table1[[#This Row],[Số HĐ]]=BBVC!$R$2,MAX(DATA!A26:A26)+1,"") | B27: 18 | C27: 46175 | D27: 2500763469 | E27: =VLOOKUP(Table1[[#This Row],[MST]],Table2[#All],2,0) -> CÔNG TY TNHH CÁT SỎI THUỶ MỘC PHÁT | F27: =VLOOKUP(Table1[[#This Row],[MST]],Table2[#All],3,0) -> Thôn Nội, Xã Vĩnh An, Tỉnh Phú Thọ, Việt Nam | G27: Cước vận chuyển quả chuẩn phục vụ kiểm định từ Tề Lỗ, Phú Thọ đến bến cát thôn Đa Cai, Xã Sơn Đông, Tỉnh Phú Thọ | H27: Chuyến | I27: 1 | J27: 4000000 | K27: =Table1[[#This Row],[Số lượng]]*Table1[[#This Row],[Đơn giá]] -> 4000000
A28: =IF(Table1[[#This Row],[Số HĐ]]=BBVC!$R$2,MAX(DATA!A27:A27)+1,"") | B28: 19 | C28: 46176 | D28: 0401886963 | E28: =VLOOKUP(Table1[[#This Row],[MST]],Table2[#All],2,0) -> CÔNG TY TNHH MTV CÔNG NGHỆ ĐO LƯỜNG - ĐIỀU KHIỂN VŨ DUY | F28: =VLOOKUP(Table1[[#This Row],[MST]],Table2[#All],3,0) -> K428 Tôn Đản, Phường An Khê, Thành phố Đà Nẵng, Việt Nam | G28: Cước cẩu, vận chuyển quả cân từ Tề Lỗ, Phú Thọ đến Xã Thanh Thịnh, Thái Nguyên | H28: Chuyến | I28: 1 | J28: 6500000 | K28: =Table1[[#This Row],[Số lượng]]*Table1[[#This Row],[Đơn giá]] -> 6500000
A29: =IF(Table1[[#This Row],[Số HĐ]]=BBVC!$R$2,MAX(DATA!A28:A28)+1,"") | B29: 20 | C29: 46176 | D29: 2500603377 | E29: =VLOOKUP(Table1[[#This Row],[MST]],Table2[#All],2,0) -> CÔNG TY CỔ PHẦN KIỂM ĐỊNH MKV | F29: =VLOOKUP(Table1[[#This Row],[MST]],Table2[#All],3,0) -> Đường Phạm Đình Hổ, Phường Vĩnh Yên, Tỉnh Phú Thọ, Việt Nam | G29: Cước cẩu, vận chuyển quả cân từ Tề Lỗ, Phú Thọ đi xã Kỳ Sơn, tỉnh Phú Thọ | H29: Chuyến | I29: 2 | J29: 5555555 | K29: =Table1[[#This Row],[Số lượng]]*Table1[[#This Row],[Đơn giá]]+1 -> 11111111
A30: =IF(Table1[[#This Row],[Số HĐ]]=BBVC!$R$2,MAX(DATA!A29:A29)+1,"") | B30: 21 | C30: 46177 | D30: 2300226957 | E30: =VLOOKUP(Table1[[#This Row],[MST]],Table2[#All],2,0) -> CÔNG TY TNHH HƯƠNG GIA VỊ SƠN HÀ | F30: =VLOOKUP(Table1[[#This Row],[MST]],Table2[#All],3,0) -> Phố Quế, Cụm Công nghiệp Đa nghề Đình Bảng, Phường Từ Sơn, Tỉnh Bắc Ninh, Việt Nam | G30: Cước vận chuyển xe nâng và thiết bị từ công ty TNHH Hương Gia Vị Sơn Hà thôn Yên Thành tới thôn Yên Dũng, xã Xuân Ái, Tỉnh Lào Cai | H30: Chuyến | I30: 2 | J30: 1500000 | K30: =Table1[[#This Row],[Số lượng]]*Table1[[#This Row],[Đơn giá]] -> 3000000
A31: =IF(Table1[[#This Row],[Số HĐ]]=BBVC!$R$2,MAX(DATA!A30:A30)+1,"") | B31: 22 | C31: 46177 | D31: 2500598864 | E31: =VLOOKUP(Table1[[#This Row],[MST]],Table2[#All],2,0) -> CÔNG TY TNHH CÂN ĐIỆN TỬ THẾ HỆ MỚI | F31: =VLOOKUP(Table1[[#This Row],[MST]],Table2[#All],3,0) -> Thôn Đồng Lực, Xã Hoàng An, Tỉnh Phú Thọ, Việt Nam | G31: Cước vận chuyển quả chuẩn từ Công ty TNHH Thế Hệ Mới đến P. Mỹ Lâm, Tỉnh Tuyên Quang | H31: Chuyến | I31: 1 | J31: 4500000 | K31: =Table1[[#This Row],[Số lượng]]*Table1[[#This Row],[Đơn giá]] -> 4500000
A32: =IF(Table1[[#This Row],[Số HĐ]]=BBVC!$R$2,MAX(DATA!A31:A31)+1,"") | B32: 23 | C32: 46178 | D32: 0109796541 | E32: =VLOOKUP(Table1[[#This Row],[MST]],Table2[#All],2,0) -> CÔNG TY TNHH TƯ VẤN KIỂM ĐỊNH VÀ THIẾT BỊ ĐO LƯỜNG | F32: =VLOOKUP(Table1[[#This Row],[MST]],Table2[#All],3,0) -> Số 24 Liền kề 4, KĐT Đại Thanh, Xã Đại Thanh, Thành phố Hà Nội, Việt Nam | G32: Cước cẩu, vận chuyển quả chuẩn từ Tề Lỗ, Phú Thọ đi Văn Yên, Lào Cai | H32: Chuyến | I32: 1 | J32: 11000000 | K32: =Table1[[#This Row],[Số lượng]]*Table1[[#This Row],[Đơn giá]] -> 11000000
A33: =IF(Table1[[#This Row],[Số HĐ]]=BBVC!$R$2,MAX(DATA!A32:A32)+1,"") | B33: 24 | C33: 46179 | D33: 2500675251 | E33: =VLOOKUP(Table1[[#This Row],[MST]],Table2[#All],2,0) -> CÔNG TY TNHH GIẢI PHÁP CÔNG NGHỆ VINACO VIỆT NAM | F33: =VLOOKUP(Table1[[#This Row],[MST]],Table2[#All],3,0) -> Thôn Vân Nội, Xã Hội Thịnh, Tỉnh Phú Thọ, Việt Nam | G33: Cước vận chuyển sắt từ Đông Anh về Công ty TNHH Giải Pháp Công Nghệ Vinaco Việt Nam tại Phú Thọ phục vụ sản xuất | H33: Chuyến | I33: 1 | J33: 3000000 | K33: =Table1[[#This Row],[Số lượng]]*Table1[[#This Row],[Đơn giá]] -> 3000000
A34: =IF(Table1[[#This Row],[Số HĐ]]=BBVC!$R$2,MAX(DATA!A33:A33)+1,"") | B34: 25 | C34: 46181 | D34: 0105436996 | E34: =VLOOKUP(Table1[[#This Row],[MST]],Table2[#All],2,0) -> CÔNG TY TNHH SẢN XUẤT CÔNG NGHỆ TÂN NAM PHÁT | F34: =VLOOKUP(Table1[[#This Row],[MST]],Table2[#All],3,0) -> Số 45B2 ngõ 649 đường Lĩnh Nam, Phường Vĩnh Hưng, Thành phố Hà Nội | G34: Cước cẩu, vận chuyển quả chuẩn đi Phong Châu, Phú Thọ và cẩu phục vụ kiểm định | H34: Chuyến | I34: 1 | J34: 4500000 | K34: =Table1[[#This Row],[Số lượng]]*Table1[[#This Row],[Đơn giá]] -> 4500000
A35: =IF(Table1[[#This Row],[Số HĐ]]=BBVC!$R$2,MAX(DATA!A34:A34)+1,"") | B35: 25 | C35: 46181 | D35: 0105436996 | E35: =VLOOKUP(Table1[[#This Row],[MST]],Table2[#All],2,0) -> CÔNG TY TNHH SẢN XUẤT CÔNG NGHỆ TÂN NAM PHÁT | F35: =VLOOKUP(Table1[[#This Row],[MST]],Table2[#All],3,0) -> Số 45B2 ngõ 649 đường Lĩnh Nam, Phường Vĩnh Hưng, Thành phố Hà Nội | G35: Cước cẩu, vận chuyển quả chuẩn đi TP Hòa Bình, Phú Thọ và cẩu phục vụ kiểm định | H35: Chuyến | I35: 1 | J35: 5000000 | K35: =Table1[[#This Row],[Số lượng]]*Table1[[#This Row],[Đơn giá]] -> 5000000
A36: =IF(Table1[[#This Row],[Số HĐ]]=BBVC!$R$2,MAX(DATA!A35:A35)+1,"") | B36: 26 | C36: 46182 | D36: 0109205534 | E36: =VLOOKUP(Table1[[#This Row],[MST]],Table2[#All],2,0) -> CÔNG TY TNHH TM VÀ DỊCH VỤ TỰ ĐỘNG HÓA THÀNH CÔNG | F36: =VLOOKUP(Table1[[#This Row],[MST]],Table2[#All],3,0) -> Thửa đất số 171CBĐ 03, Tổ 5 Phường Yên Nghĩa, Thành Phố Hà Nội | G36: Cước cẩu, vận chuyển bàn cân từ Hội Thịnh, Phú Thọ đến 23 Nam Hồng, Đông Anh, TP Hà Nội | H36: Chuyến | I36: 1 | J36: 3000000 | K36: =Table1[[#This Row],[Số lượng]]*Table1[[#This Row],[Đơn giá]] -> 3000000
A37: =IF(Table1[[#This Row],[Số HĐ]]=BBVC!$R$2,MAX(DATA!A36:A36)+1,"") | B37: 26 | C37: 46182 | D37: 0109205534 | E37: =VLOOKUP(Table1[[#This Row],[MST]],Table2[#All],2,0) -> CÔNG TY TNHH TM VÀ DỊCH VỤ TỰ ĐỘNG HÓA THÀNH CÔNG | F37: =VLOOKUP(Table1[[#This Row],[MST]],Table2[#All],3,0) -> Thửa đất số 171CBĐ 03, Tổ 5 Phường Yên Nghĩa, Thành Phố Hà Nội | G37: Cước cẩu, vận chuyển quả chuẩn từ Tề Lỗ, Phú Thọ đến 23 Nam Hồng, Đông Anh, TP Hà Nội phục vụ kiểm định | H37: Chuyến | I37: 1 | J37: 3000000 | K37: =Table1[[#This Row],[Số lượng]]*Table1[[#This Row],[Đơn giá]] -> 3000000
A38: =IF(Table1[[#This Row],[Số HĐ]]=BBVC!$R$2,MAX(DATA!A37:A37)+1,"") | B38: 27 | C38: 46183 | D38: 2500561310 | E38: =VLOOKUP(Table1[[#This Row],[MST]],Table2[#All],2,0) -> CÔNG TY TNHH MỘT THÀNH VIÊN CÂN ĐIỆN TỬ VĨNH PHÚC | F38: =VLOOKUP(Table1[[#This Row],[MST]],Table2[#All],3,0) -> Số nhà 25, Tổ dân phố Đậu, Phường Vĩnh Phúc, Tỉnh Phú Thọ, Việt Nam | G38: Cước cẩu, vận chuyển quả chuẩn từ Tề Lỗ, Phú Thọ đến Phượng Sơn, Bắc Ninh | H38: Chuyến | I38: 1 | J38: 5555555 | K38: =Table1[[#This Row],[Số lượng]]*Table1[[#This Row],[Đơn giá]] -> 5555555
A39: =IF(Table1[[#This Row],[Số HĐ]]=BBVC!$R$2,MAX(DATA!A38:A38)+1,"") | B39: 28 | C39: 46188 | D39: 0107705669 | E39: =VLOOKUP(Table1[[#This Row],[MST]],Table2[#All],2,0) -> CÔNG TY TNHH THIẾT BỊ ĐO LƯỜNG VÀ CÔNG NGHIỆP 247 | F39: =VLOOKUP(Table1[[#This Row],[MST]],Table2[#All],3,0) -> Số 5, Ngõ 254, Đường Mỹ Đình, Phường Từ Liêm, Thành phố Hà Nội, Việt Nam | G39: Cước cẩu, vận chuyển quả chuẩn từ Tề Lỗ, Phú Thọ đi Xã Đoan Hùng, Tỉnh Phú Thọ | H39: Chuyến | I39: 1 | J39: 4500000 | K39: =Table1[[#This Row],[Số lượng]]*Table1[[#This Row],[Đơn giá]] -> 4500000
A40: =IF(Table1[[#This Row],[Số HĐ]]=BBVC!$R$2,MAX(DATA!A39:A39)+1,"") | B40: 29 | C40: 46189 | D40: 0109205534 | E40: =VLOOKUP(Table1[[#This Row],[MST]],Table2[#All],2,0) -> CÔNG TY TNHH TM VÀ DỊCH VỤ TỰ ĐỘNG HÓA THÀNH CÔNG | F40: =VLOOKUP(Table1[[#This Row],[MST]],Table2[#All],3,0) -> Thửa đất số 171CBĐ 03, Tổ 5 Phường Yên Nghĩa, Thành Phố Hà Nội | G40: Cước cẩu, vận chuyển bàn cân từ Hội Thịnh, Phú Thọ đến Xã Tô Mậu, Tỉnh Lào Cai | H40: Chuyến | I40: 1 | J40: 16000000 | K40: =Table1[[#This Row],[Số lượng]]*Table1[[#This Row],[Đơn giá]] -> 16000000
A41: =IF(Table1[[#This Row],[Số HĐ]]=BBVC!$R$2,MAX(DATA!A40:A40)+1,"") | B41: 30 | C41: 46191 | D41: 2500649903 | E41: =VLOOKUP(Table1[[#This Row],[MST]],Table2[#All],2,0) -> CÔNG TY TNHH H2Y VINA | F41: =VLOOKUP(Table1[[#This Row],[MST]],Table2[#All],3,0) -> Khu đô thị Đồng Sơn, tổ 9, Phường Phúc Yên, Tỉnh Phú Thọ, Việt Nam | G41: Cước vận chuyển chặng Khai Quang-Phú Hà | H41: Chuyến | I41: 1 | J41: 4629630 | K41: =Table1[[#This Row],[Số lượng]]*Table1[[#This Row],[Đơn giá]] -> 4629630
A42: =IF(Table1[[#This Row],[Số HĐ]]=BBVC!$R$2,MAX(DATA!A41:A41)+1,"") | B42: 31 | C42: 46194 | D42: 2500675251 | E42: =VLOOKUP(Table1[[#This Row],[MST]],Table2[#All],2,0) -> CÔNG TY TNHH GIẢI PHÁP CÔNG NGHỆ VINACO VIỆT NAM | F42: =VLOOKUP(Table1[[#This Row],[MST]],Table2[#All],3,0) -> Thôn Vân Nội, Xã Hội Thịnh, Tỉnh Phú Thọ, Việt Nam | G42: Cước cẩu, vận chuyển quả cân chuẩn từ xã Tề Lỗ đi xã Xuân Lãng, tỉnh Phú Thọ , biển kiểm soát 19H-147.98 | H42: Ca cẩu | I42: 1 | J42: 3500000 | K42: =Table1[[#This Row],[Số lượng]]*Table1[[#This Row],[Đơn giá]] -> 3500000
...

Sheet BBVC
B1: CỘNG HÒA XÃ HỘI CHỦ NGHĨA VIỆT NAM
B2: Độc lập - Tự do - Hạnh phúc | Q2: Số HĐ | R2: 10
B4: BIÊN BẢN VẬN CHUYỂN | R4: =IFERROR(VLOOKUP($R$2,Table1[[#All],[Số HĐ]:[Thành tiền]],2,0),"") -> 46165 | S4: 23
H5: Số : | I5: =S4&""&0&""&S5&"/"&"2026"&"/BBVC" -> 2305/2026/BBVC | S5: =MONTH(R4) -> 5
D7: Hôm nay, | E7: =R4 -> 46165 | H7: . Tại văn phòng quý khách hàng, chúng tôi gồm có:
B8: BÊN VẬN CHUYỂN (BÊN A) | G8: : CÔNG TY TNHH VẬN TẢI ĐẠI LỘ XANH
B9: MST | E9: 2500774911
B10: Địa chỉ | E10: Số nhà 306, đường 303, thôn Giã Bàng, Xã Tề Lỗ, Tỉnh Phú Thọ, Việt Nam
B11: Đại diện | E11: Ông NGUYỄN KIM QUYẾT | L11: Chức vụ : Giám đốc
B12: Biển số xe | E12: 19H-147.98
B14: BÊN THUÊ VẬN CHUYỂN (BÊN B) : | G14: =IFERROR(VLOOKUP($R$2,Table1[[#All],[Số HĐ]:[Thành tiền]],4,0),"") -> CÔNG TY CỔ PHẦN TECON88
B15: MST | E15: =IFERROR(VLOOKUP($R$2,Table1[[#All],[Số HĐ]:[Thành tiền]],3,0),"") -> 2500708852
B16: Địa chỉ | E16: =IFERROR(VLOOKUP($R$2,Table1[[#All],[Số HĐ]:[Thành tiền]],5,0),"") -> Số 59 Đường Quang Trung, Phố Tiên, Phường Vĩnh Yên, Tỉnh Phú Thọ, Việt Nam
B17: Đại diện | L17: Chức vụ :
B19: I. NỘI DUNG VẬN CHUYỂN
B20: Bên B đồng ý giao, Bên A đồng ý nhận vận chuyển hàng hóa, máy móc thiết bị, vật tư với số lượng và đơn
B21: giá vận chuyển cụ thể như sau:
B23: STT | C23: Tên hàng hàng hóa , dịch vụ | L23: ĐVT | M23: Số lượng | N23: Đơn giá | O23: Thành tiền
A24: 1 | B24: 1 | C24: =IFERROR(VLOOKUP(A24,DATA!A7:K2543,7,0),"") -> Cước vận chuyển thép hình từ Tề Lỗ, Phú Thọ đến Phường Vĩnh Yên, Phú Thọ | L24: =IFERROR(VLOOKUP(A24,DATA!A7:K110,8,0),"") -> Chuyến | M24: =IFERROR(VLOOKUP(A24,DATA!A7:K110,9,0),"") -> 1 | N24: =IFERROR(VLOOKUP(A24,DATA!A7:K110,10,0),"") -> 2000000 | O24: =IFERROR(VLOOKUP(A24,DATA!A7:K110,11,0),"") -> 2000000
A25: 2 | B25: 2 | C25: =IFERROR(VLOOKUP(A25,DATA!A8:K2544,7,0),"") | L25: =IFERROR(VLOOKUP(A25,DATA!A8:K110,8,0),"") | M25: =IFERROR(VLOOKUP(A25,DATA!A8:K110,9,0),"") | N25: =IFERROR(VLOOKUP(A25,DATA!A8:K110,10,0),"") | O25: =IFERROR(VLOOKUP(A25,DATA!A8:K110,11,0),"")
A26: 3 | C26: =IFERROR(VLOOKUP(A26,DATA!A9:K12,7,0),"") | L26: =IFERROR(VLOOKUP(A26,DATA!A9:K12,8,0),"") | M26: =IFERROR(VLOOKUP(A26,DATA!A9:K12,9,0),"") | N26: =IFERROR(VLOOKUP(A26,DATA!A9:K12,10,0),"") | O26: =IFERROR(VLOOKUP(A26,DATA!A9:K12,11,0),"")
B27: Cộng | O27: =SUM(O24:O26) -> 2000000
B28: Thuế GTGT 8% | O28: =O27*8% -> 160000
B29: Tổng thanh toán | O29: =O27+O28 -> 2160000
B30: Số tiền bằng chữ : | F30: =[1]!VND(BBVC!O29, TRUE,1,"đồng","xu") -> Hai triệu, một trăm sáu mươi ngàn đồng
B32: II. KẾT LUẬN
B33: Hai bên cùng nhau xác nhận đã giao nhận đúng, đủ số lượng hàng vận chuyển chuyển theo đúng lộ trình đã
B34: thống nhất.
B35: Biên bản vận chuyển được lập thành 02 bản, có giá trị pháp lý như nhau, mỗi bên giữ 01 bản.
E37: ĐẠI DIỆN BÊN A | M37: ĐẠI DIỆN BÊN B
E38: (Ký,ghi rõ họ tên) | M38: (Ký,ghi rõ họ tên)
D43: NGUYỄN KIM QUYẾT

Sheet BBTLHĐ
A1: CỘNG HOÀ XÃ HỘI CHỦ NGHĨA VIỆT NAM | P1: ngày | Q1: 28
A2: Độc lập – Tự do – Hạnh phúc | P2: tháng | Q2: 05
P3: năm 2026
A5: BIÊN BẢN NGHIỆM THU KIÊM THANH LÝ HỢP ĐỒNG | P5: MST : | Q5: 2600706055
A7: - Căn cứ Hợp đồng vận chuyển số | G7: 22052026/HĐKT ký ngày 22 tháng 05 năm 2026 giữa CÔNG TY TNHH
A8: VẬN TẢI ĐẠI LỘ XANH và | F8: =_xlfn.IFNA(VLOOKUP($Q$5,Table2[#All],2,0),"") -> TRUNG TÂM KỸ THUẬT TIÊU CHUẨN ĐO LƯỜNG CHẤT LƯỢNG
A9: - Căn cứ kết quả thực tế trong quá trình thực hiện hợp đồng đã ký.
A10: Hôm nay, | B10: 46167 | H10: ="tại văn phòng"&" "&F8&" "&"chúng tôi gồm có :" -> tại văn phòng TRUNG TÂM KỸ THUẬT TIÊU CHUẨN ĐO LƯỜNG CHẤT LƯỢNG chúng tôi gồm có :
A11: BÊN A | B11: =_xlfn.IFNA(VLOOKUP($Q$5,Table2[#All],2,0),"") -> TRUNG TÂM KỸ THUẬT TIÊU CHUẨN ĐO LƯỜNG CHẤT LƯỢNG
A12: Đại diện | B12: Ông | C12: =_xlfn.IFNA(VLOOKUP($Q$5,Table2[#All],4,0),"") -> NGUYỄN HỮU HÀ | K12: Chức vụ | L12: Giám đốc
A13: Địa chỉ | B13: =_xlfn.IFNA(VLOOKUP($Q$5,Table2[#All],3,0),"") -> Đường Kim Đồng, Phường Việt Trì, T. Phú Thọ
A14: STK | B14: =_xlfn.IFNA(VLOOKUP($Q$5,Table2[#All],6,0),"") -> 118000066436 | K14: =_xlfn.IFNA(VLOOKUP($Q$5,Table2[#All],7,0),"") -> Tại ngân hàng TMCP Công thương Việt Nam - CN Hùng Vương
A15: MST | B15: =_xlfn.IFNA(VLOOKUP($Q$5,Table2[#All],1,0),"") -> 2600706055
A17: BÊN B | B17: CÔNG TY TNHH VẬN TẢI ĐẠI LỘ XANH
A18: Đại diện | B18: Ông | C18: NGUYỄN KIM QUYẾT | K18: Chức vụ | L18: Giám đốc
A19: Địa chỉ | B19: Số nhà 306, Đường 303, Thôn Giã Bàng, Xã Tề Lỗ, Tỉnh Phú Thọ, Việt Nam
A20: STK | B20: 110003058298 Tại ngân hàng Vietinbank - PDG Bắc Yên Lạc
A21: Email | B21: vantaidailoxanh2026@gmail.com
A22: MST | B22: 2500774911
A24: Hai bên đã cùng nhau kiểm tra xác nhận, đánh giá việc thực hiện các nội dung công việc thỏa thuận theo hợp
A25: đồng đã ký như sau:
A26: 1. Bên B đã thực hiện các công việc như sau: Cẩu quả chuẩn M1 từ Trung tâm Kỹ thuật Tiêu chuẩn Đo
A27: lường Chất lượng đến Công ty cổ phần công nghệ FATA (Lô CN01, Khu Công Nghiệp Thụy Vân, Xã Hy
A28: Cương, Tỉnh Phú Thọ, Việt Nam) để kiểm định cân ô tô và ngược lại.
A29: 2. Căn cứ đơn giá theo thỏa thuận tại hợp đồng | J29: 22052026/HĐKT ký ngày 22 tháng 05 năm 2026 Bên B phải
A30: thanh toán cho Bên B chi phí thực hiện hợp đồng: 16.200.000 đồng (Mười sáu triệu hai trăm nghìn
A31: đồng chẵn./.)(Giá trên đã bao gồm thuế GTGT).
A32: Hình thức thanh toán: | F32: Tiền mặt hoặc Chuyển khoản.
A33: Bên B đã bàn giao cho Bên A hoá đơn tài chính để Bên A thực hiện việc thanh quyết toán chi phí thực hiện hợp
A34: đồng theo thỏa thuận tại hợp đồng đã ký.
A35: 3. Hai bên thống nhất xác nhận thực hiện hoàn thành các công việc theo thỏa thuận tại Hợp đồng đã ký để phục
A36: vụ việc thanh quyết toán chi phí thực hiện hợp đồng.
A37: Hợp đồng này sẽ hết hiệu lực sau khi Bên A hoàn thành việc thanh quyết toán kinh phí thực hiện hợp đồng cho
A38: Bên B.
A39: Biên bản này được lập thành 02 bản mỗi bên giữ 01 bản có giá trị pháp lý như nhau, Biên bản này sau khi lập xong
A40: được đọc lại cho các bên tham dự cùng nghe và nhất trí cùng nhau ký vào biên bản.
E42: ĐẠI DIỆN BÊN A | K42: ĐẠI DIỆN BÊN B
A49: Lê Hồng Phong | E49: Nguyễn Hải Đăng

Sheet ĐNTT
A1: CÔNG TY TNHH VẬN TẢI ĐẠI LỘ XANH | H1: CỘNG HÒA XÃ HỘI CHỦ NGHĨA VIỆT NAM
A2: -------------------- | I2: Độc lập – Tự do- Hạnh phúc | M2: HĐ số : | N2: 54 | O2: =IFERROR(VLOOKUP($N$2,Table1[[#All],[Số HĐ]:[Thành tiền]],2,0),"") -> 46229
A3: Số: .../ĐNTT-ĐLX | I3: -------------------- | N3: =IFERROR(VLOOKUP($N$2,Table1[[#All],[Số HĐ]:[Thành tiền]],6,0),"") -> Cước cẩu, vận chuyển quả chuẩn từ Tề Lỗ, Phú Thọ đến Phường Phúc Yên, Phú Thọ
A4: Vv: Thanh toán hóa đơn | M4: tổng tiền | N4: =IFERROR(VLOOKUP($N$2,Table1[[#All],[Số HĐ]:[Thành tiền]],10,0),"") -> 14500000 | P4: =N4+N4*8% -> 15660000
I5: Phú Thọ, | J5: ngày 28 tháng 07 năm 2026 | M5: vận chuyển | N5: quả chuẩn
M6: địa điểm đến : | N6: Tề Lỗ, Phú Thọ
A7: ĐỀ NGHỊ THANH TOÁN | M7: địa điểm đi : | N7: Phường Phúc Yên, Phú Thọ
B9: Kính gửi: | C9: =IFERROR(VLOOKUP($N$2,Table1[[#All],[Số HĐ]:[Thành tiền]],4,0),"") -> CÔNG TY TNHH ỨNG DỤNG GIẢI PHÁP CÔNG NGHỆ
A10: Trước tiên xin chân thành cảm ơn quý công ty đã tin tưởng và lựa chọn Công ty chúng tôi.
A11: Chúng tôi đã vận chuyển | E11: =N5&" từ"&" " &N6&" đi "&N7&" BKS 19H-147.98." -> quả chuẩn từ Tề Lỗ, Phú Thọ đi Phường Phúc Yên, Phú Thọ BKS 19H-147.98.
A12: Tổng cước vận chuyển là | E12: =P4 -> 15660000 | G12: ="(đã bao gồm thuế GTGT) và đã phát hành Hóa đơn số: 000000"&N2 -> (đã bao gồm thuế GTGT) và đã phát hành Hóa đơn số: 00000054
A13: =IFERROR(VLOOKUP($N$2,Table1[[#All],[Số HĐ]:[Thành tiền]],2,0),"") -> 46229
A14: Bằng công văn này, kính đề nghị Quý Công ty thanh toán cho chúng tôi số tiền là: | K14: =P4 -> 15660000
B15: Số tiền bằng chữ : | D15: =[1]!VND(ĐNTT!K14, TRUE,1,"đồng","xu") -> Mười lăm triệu, sáu trăm sáu mươi ngàn đồng
A16: Thông Tin Thụ Hưởng:
A17: - Công Ty TNHH Vận tải Đại Lộ Xanh.
A18: - Số TK: 110003058298
A19: - Tại Ngân hàng Vietinbank – PGD Bắc Yên Lạc.
A20: Xin trân trọng cảm ơn!
A22: Nơi nhận: | H22: CÔNG TY TNHH VẬN TẢI ĐẠI LỘ XANH
A23: - Như trên
A24: - Lưu VP Công ty
