Workbook
Name NgayCongChuan: BCC!$AJ$5

Sheet Mức lương
A1: CÔNG TY TNHH VẬN TẢI ĐẠI LỘ XANH
A2: Địa chỉ: Số nhà 306, Đường 303, Thôn Giã Bàng, Xã Tề Lỗ, Tỉnh Phú Thọ
E3: QUYẾT ĐỊNH LƯƠNG VÀ THỜI GIAN LÀM VIỆC CỦA LAO ĐỘNG
A5: STT | B5: HỌ VÀ TÊN | C5: CHỨC VỤ | D5: MỨC LƯƠNG
E6: ĐIỆN THOẠI | F6: TRÁCH NHIỆM | G6: TIỀN ĂN | H6: LƯƠNG THỬ VIỆC | I6: LƯƠNG BH | J6: THỜI GIAN HỌC VIỆC | K6: THỜI GIAN THỬ VIỆC | L6: THỜI GIAN CHÍNH THỨC | M6: THỜI GIAN NGHỈ VIỆC | N6: GHI CHÚ
B7: 1 | C7: 2 | D7: 3 | E7: 4 | F7: 5 | H7: 7 | I7: 8 | J7: 9 | K7: 10 | L7: 11 | M7: 12 | N7: 13
A8: =IF(ISNUMBER(D8),COUNT($D$8:D8),"") -> 1 | B8: NGUYỄN KIM QUYẾT | C8: Giám Đốc | D8: 6000000 | E8: 2000000 | F8: 3000000 | G8: 1000000 | I8: 6000000
A9: I | B9: BỘ PHẬN LÁI XE
A10: =IF(ISNUMBER(D10),COUNT($D$8:D10),"") -> 2 | B10: NGUYỄN VĂN LỢI | C10: Tài xế xe tải | D10: 5500000 | E10: 500000 | F10: 500000 | G10: 1000000 | I10: 5500000 | L10: 46296 | N10: Mức đầy đủ; hệ thống tự quy đổi theo công thực tế ở BCC (T7: 17 công)

Sheet BCC
A1: CÔNG TY TNHH VẬN TẢI ĐẠI LỘ XANH
A2: Địa chỉ: Số nhà 306, Đường 303, Thôn Giã Bàng, Xã Tề Lỗ, Tỉnh Phú Thọ
A3: BẢNG CHẤM CÔNG
M4: Tháng | O4: 10
M5: Năm | O5: 2026 | AJ5: 26
A6: STT | B6: Họ và tên | C6: Chức vụ | D6: Ngày trong tháng | AJ6: Công làm việc thực tế (*) | AK6: Ngày nghỉ có hưởng lương | AQ6: Số giờ tăng ca (OT) | AT6: Ngày nghỉ không hưởng lương | AY6: Ghi chú | AZ6: Kiểm tra trần TC (≤40h/tháng) | BA6: Ghi chú
D7: Loại | E7: =DATE(O5,O4,1) -> 46296 | F7: =+E7+1 -> 46297 | G7: =+F7+1 -> 46298 | H7: =+G7+1 -> 46299 | I7: =+H7+1 -> 46300 | J7: =+I7+1 -> 46301 | K7: =+J7+1 -> 46302 | L7: =+K7+1 -> 46303 | M7: =+L7+1 -> 46304 | ... AF7: =+AE7+1 -> 46323 | AG7: =IF(AF7="","",IF(MONTH(AF7+1)=MONTH($E$7),AF7+1,"")) -> 46324 | AH7: =IF(AG7="","",IF(MONTH(AG7+1)=MONTH($E$7),AG7+1,"")) -> 46325 | AI7: =IF(AH7="","",IF(MONTH(AH7+1)=MONTH($E$7),AH7+1,"")) -> 46326 | AK7: Nghỉ phép năm (P) | AL7: Nghỉ phép lễ (L) | AM7: Hội nghị nghỉ (H) | AN7: Nghỉ bù (NB) | AO7: Tai nạn nam (T) | AP7: Thâm niên (TN) | AQ7: Ngày thường (150%) | AR7: Chủ nhật | AS7: Ngày lễ | AT7: Nghỉ không hưởng lương (KL) | AU7: Nghỉ bản thân ốm (OM) | AV7: Nghỉ con ốm (CO) | AW7: Nghỉ thai sản (TS) | AX7: Nghỉ lao động nghĩa vụ (LĐ)
E8: =IF(WEEKDAY(E7)=1,"CN","T"&WEEKDAY(E7)) -> T5 | F8: =IF(WEEKDAY(F7)=1,"CN","T"&WEEKDAY(F7)) -> T6 | G8: =IF(WEEKDAY(G7)=1,"CN","T"&WEEKDAY(G7)) -> T7 | H8: =IF(WEEKDAY(H7)=1,"CN","T"&WEEKDAY(H7)) -> CN | I8: =IF(WEEKDAY(I7)=1,"CN","T"&WEEKDAY(I7)) -> T2 | J8: =IF(WEEKDAY(J7)=1,"CN","T"&WEEKDAY(J7)) -> T3 | K8: =IF(WEEKDAY(K7)=1,"CN","T"&WEEKDAY(K7)) -> T4 | L8: =IF(WEEKDAY(L7)=1,"CN","T"&WEEKDAY(L7)) -> T5 | ... AF8: =IF(WEEKDAY(AF7)=1,"CN","T"&WEEKDAY(AF7)) -> T4 | AG8: =IF(AG7="","",IF(WEEKDAY(AG7)=1,"CN","T"&WEEKDAY(AG7))) -> T5 | AH8: =IF(AH7="","",IF(WEEKDAY(AH7)=1,"CN","T"&WEEKDAY(AH7))) -> T6 | AI8: =IF(AI7="","",IF(WEEKDAY(AI7)=1,"CN","T"&WEEKDAY(AI7))) -> T7
A9: =IF(B9="","",COUNTIF($D$9:D9,"HC")) -> 1 | B9: =IF('Mức lương'!B8="","",'Mức lương'!B8) -> NGUYỄN KIM QUYẾT | C9: =IF(B9="","",IFERROR(IF(INDEX('Mức lương'!$C$8:$C$62,MATCH($B9,'Mức lương'!$B$8:$B$62,0))="","",INDEX('Mức lương'!$C$8:$C$62,MATCH($B9,'Mức lương'!$B$8:$B$62,0))),"")) -> Giám Đốc | D9: HC | E9: x | F9: x | G9: x | H9: x | J9: x | K9: x | L9: x | M9: x | N9: x | O9: x | Q9: x | R9: x | S9: x | T9: x | U9: x | V9: x | X9: x | Y9: x | Z9: x | AA9: x | AB9: x | AC9: x | AE9: x | AF9: x | AG9: x | AH9: x | AI9: x | AJ9: =COUNTIF(E9:AI9,"X")+COUNTIF(E9:AI9,"NL")+COUNTIF(E9:AI9,"x/2")/2+COUNTIF(E9:AI9,"NL/2")/2+COUNTIF(E9:AI9,"P")+COUNTIF(E9:AI9,"P/2")/2 -> 27 | AK9: =COUNTIF(E9:AI9,"P")+COUNTIF(E9:AI9,"P/2")*0.5 -> 0 | AL9: =COUNTIF(E9:AI9,"L") -> 0 | AM9: =COUNTIF(E9:AI9,"H") -> 0 | AN9: =COUNTIF(E9:AI9,"NB") -> 0 | AO9: =COUNTIF(E9:AI9,"T") -> 0 | AP9: =COUNTIF(E9:AI9,"TN") -> 0 | AQ9: =SUM(E10:AI10)-AR9-AS9 -> 0 | AR9: =SUMPRODUCT(($E$8:$AI$8="CN")*($E9:$AI9<>"L"),$E10:$AI10) -> 0 | AS9: =SUMPRODUCT(--($E9:$AI9="L"),$E10:$AI10) -> 0 | AT9: =COUNTIF(E9:AI9,"KL") -> 0 | AU9: =COUNTIF(E9:AI9,"OM") -> 0 | AV9: =COUNTIF(E9:AI9,"CO") -> 0 | AW9: =COUNTIF(E9:AI9,"TS") -> 0 | AX9: =COUNTIF(E9:AI9,"LD") -> 0 | AZ9: =IF(SUM(AQ9:AS9)>40,"Vượt trần!","Đạt") -> Đạt
D10: Tăng ca
A11: =IF('Mức lương'!A9="","",'Mức lương'!A9) -> I | B11: =IF('Mức lương'!B9="","",'Mức lương'!B9) -> BỘ PHẬN LÁI XE
A12: =IF(B12="","",COUNTIF($D$9:D12,"HC")) -> 2 | B12: =IF('Mức lương'!B10="","",'Mức lương'!B10) -> NGUYỄN VĂN LỢI | C12: =IF(B12="","",IFERROR(IF(INDEX('Mức lương'!$C$8:$C$62,MATCH($B12,'Mức lương'!$B$8:$B$62,0))="","",INDEX('Mức lương'!$C$8:$C$62,MATCH($B12,'Mức lương'!$B$8:$B$62,0))),"")) -> Tài xế xe tải | D12: HC | E12: x | F12: x | G12: x | H12: x | J12: x | K12: x | L12: x | M12: x | N12: x | O12: x | Q12: x | R12: x | S12: x | T12: x | U12: x | V12: x | X12: x | Y12: O | Z12: O | AA12: O | AB12: O | AC12: O | AE12: O | AF12: O | AG12: O | AH12: O | AI12: O | AJ12: =COUNTIF(E12:AI12,"X")+COUNTIF(E12:AI12,"NL")+COUNTIF(E12:AI12,"x/2")/2+COUNTIF(E12:AI12,"NL/2")/2+COUNTIF(E12:AI12,"P")+COUNTIF(E12:AI12,"P/2")/2 -> 17 | AK12: =COUNTIF(E12:AI12,"P")+COUNTIF(E12:AI12,"P/2")*0.5 -> 0 | AL12: =COUNTIF(E12:AI12,"L") -> 0 | AM12: =COUNTIF(E12:AI12,"H") -> 0 | AN12: =COUNTIF(E12:AI12,"NB") -> 0 | AO12: =COUNTIF(E12:AI12,"T") -> 0 | AP12: =COUNTIF(E12:AI12,"TN") -> 0 | AQ12: =SUM(E13:AI13)-AR12-AS12 -> 0 | AR12: =SUMPRODUCT(($E$8:$AI$8="CN")*($E12:$AI12<>"L"),$E13:$AI13) -> 0 | AS12: =SUMPRODUCT(--($E12:$AI12="L"),$E13:$AI13) -> 0 | AT12: =COUNTIF(E12:AI12,"KL") -> 0 | AU12: =COUNTIF(E12:AI12,"OM") -> 0 | AV12: =COUNTIF(E12:AI12,"CO") -> 0 | AW12: =COUNTIF(E12:AI12,"TS") -> 0 | AX12: =COUNTIF(E12:AI12,"LD") -> 0 | AZ12: =IF(SUM(AQ12:AS12)>40,"Vượt trần!","Đạt") -> Đạt
D13: Tăng ca
B16: Ký hiệu chấm công
B17: I. Chấm công tính lương ngày đi làm | S17: II. Nghỉ có hưởng lương | AF17: III. Nghỉ không hưởng lương | AT17: IV. Quy ước màu nền | BT17: IV. Quy ước màu nền
B18: X | C18: Chấm công làm việc ngày thường | S18: P | T18: Chấm phép năm | AF18: KL | AG18: Nghỉ không hưởng lương | AT18: Ô người dùng được nhập | BT18: Ô người dùng được nhập
B19: X/2 | C19: Chấm công làm việc 1/2 ngày thường | S19: P/2 | T19: Chấm 1/2 ngày phép năm | AF19: OM | AG19: Nghỉ bản thân ốm (Có giấy nghỉ ốm do bệnh viện cấp) | AT19: Ô tự động | BT19: Ô tự động
S20: L | T20: Ngày lễ | AF20: CO | AG20: Nghỉ con ốm (Có giấy nghỉ con ốm do bệnh viện cấp) | AT20: Tiêu đề | BT20: Tiêu đề
S21: H | T21: Hội nghị, học tập | AF21: TS | AG21: Nghỉ thai sản | AT21: Ngày nghỉ cuối tuần và ngày lễ | BT21: Ngày nghỉ cuối tuần và ngày lễ
S22: NB | T22: Nghỉ bù | AF22: LĐ | AG22: Lao động nghĩa vụ | AT22: Chấm công giờ hành chính (bằng ký hiệu đã quy ước) | BT22: Chấm công giờ hành chính (bằng ký hiệu đã quy ước)
S23: T | T23: Nghỉ tai nạn | AT23: Chấm giờ tăng ca (Nhập số giờ tăng ca) | BT23: Chấm giờ tăng ca (Nhập số giờ tăng ca)
D25: Người lập | AF25: Ban QLTN | AT25: Lãnh đạo Công ty | BT25: Lãnh đạo Công ty
B32: Hướng dẫn sử dụng:
B33: 1. Chọn tháng chấm công
B34: - Tại ô Tháng/Năm trên đầu bảng, nhập tháng cần chấm công theo định dạng:

Sheet Thưởng KPI+Định mức
A1: ="BẢNG THEO DÕI TRỪ BONUS TÍNH VÀO LƯƠNG THÁNG "&BCC!O4&"/"&BCC!O5 -> BẢNG THEO DÕI TRỪ BONUS TÍNH VÀO LƯƠNG THÁNG 10/2026
A2: STT | B2: Họ và tên | C2: Chức vụ | D2: Thưởng + Định mức | G2: Tổng | H2: TÍNH THUẾ TNCN THÁNG | I2: Tiền Dư
D3: Tạm ứng | E3: Thưởng KPI KD & sale, Bốc xếp | F3: Lương Chuyến LX
B4: 1 | C4: 2 | D4: 3 | E4: 4 | F4: 5 | G4: 6 | H4: 7 | I4: 8
A5: =IF('Mức lương'!A8="","",'Mức lương'!A8) -> 1 | B5: =IF('Mức lương'!B8="","",'Mức lương'!B8) -> NGUYỄN KIM QUYẾT | C5: =IF(B5="","",IFERROR(IF(INDEX('Mức lương'!$C$8:$C$62,MATCH($B5,'Mức lương'!$B$8:$B$62,0))="","",INDEX('Mức lương'!$C$8:$C$62,MATCH($B5,'Mức lương'!$B$8:$B$62,0))),"")) -> Giám Đốc | G5: =SUM(D5:F5) -> 0 | H5: =G5 -> 0 | I5: =G5-H5 -> 0
A6: =IF('Mức lương'!A9="","",'Mức lương'!A9) -> I | B6: =IF('Mức lương'!B9="","",'Mức lương'!B9) -> BỘ PHẬN LÁI XE | C6: =IF(B6="","",IFERROR(IF(INDEX('Mức lương'!$C$8:$C$62,MATCH($B6,'Mức lương'!$B$8:$B$62,0))="","",INDEX('Mức lương'!$C$8:$C$62,MATCH($B6,'Mức lương'!$B$8:$B$62,0))),"")) | G6: =SUM(D6:F6) -> 0 | H6: =G6 -> 0 | I6: =G6-H6 -> 0
A7: =IF('Mức lương'!A10="","",'Mức lương'!A10) -> 2 | B7: =IF('Mức lương'!B10="","",'Mức lương'!B10) -> NGUYỄN VĂN LỢI | C7: =IF(B7="","",IFERROR(IF(INDEX('Mức lương'!$C$8:$C$62,MATCH($B7,'Mức lương'!$B$8:$B$62,0))="","",INDEX('Mức lương'!$C$8:$C$62,MATCH($B7,'Mức lương'!$B$8:$B$62,0))),"")) -> Tài xế xe tải | D7: 10000000 | F7: 11525473 | G7: =SUM(D7:F7) -> 21525473 | H7: =G7 -> 21525473 | I7: =G7-H7 -> 0

Sheet Người phụ thuộc
A1: STT | B1: NV | C1: Người phụ thuộc | D1: Con | E1: Cha | F1: Mẹ | G1: Ông | H1: Bà | I1: Tổng
A2: =IF('Mức lương'!A8="","",'Mức lương'!A8) -> 1 | B2: =IF('Mức lương'!B8="","",'Mức lương'!B8) -> NGUYỄN KIM QUYẾT | C2: ='Thuế TNCN'!$X$4*I2 -> 0 | I2: =SUM(D2:H2) -> 0
A3: =IF('Mức lương'!A9="","",'Mức lương'!A9) -> I | B3: =IF('Mức lương'!B9="","",'Mức lương'!B9) -> BỘ PHẬN LÁI XE | C3: ='Thuế TNCN'!$X$4*I3 -> 0 | I3: =SUM(D3:H3) -> 0
A4: =IF('Mức lương'!A10="","",'Mức lương'!A10) -> 2 | B4: =IF('Mức lương'!B10="","",'Mức lương'!B10) -> NGUYỄN VĂN LỢI | C4: ='Thuế TNCN'!$X$4*I4 -> 0 | I4: =SUM(D4:H4) -> 0

Sheet BHXH
A1: CÔNG TY TNHH VẬN TẢI ĐẠI LỘ XANH
A2: ="BẢNG TÍNH BẢO HIỂM XÃ HỘI CỦA NHÂN VIÊN THÁNG "&BCC!O4& "/"&BCC!O5 -> BẢNG TÍNH BẢO HIỂM XÃ HỘI CỦA NHÂN VIÊN THÁNG 10/2026
A3: STT | B3: Họ và tên | C3: Mã số BHXH | D3: Lương đóng BH | E3: Tiền đóng BH (32%) | F3: Trừ vào lương NLĐ | J3: DN chi trả | N3: Ghi chú
F4: BHXH(8%) | G4: BHYT(1.5%) | H4: BHTN(1%) | I4: Cộng(10.5%) | J4: BHXH(17.5%) | K4: BHYT(3%) | L4: BHTN(1%) | M4: Cộng (21.5%)
A5: =IF('Mức lương'!A8="","",'Mức lương'!A8) -> 1 | B5: =IF('Mức lương'!B8="","",'Mức lương'!B8) -> NGUYỄN KIM QUYẾT | D5: =IF($B5="","",IFERROR(IF(INDEX('Mức lương'!$I$8:$I$62,MATCH($B5,'Mức lương'!$B$8:$B$62,0))="","",INDEX('Mức lương'!$I$8:$I$62,MATCH($B5,'Mức lương'!$B$8:$B$62,0))),"")) -> 6000000 | E5: =IF($D5="","",I5+M5) -> 1920000 | F5: =IF($D5="","",$D5*'Bảng lương'!$S$7) -> 480000 | G5: =IF($D5="","",$D5*'Bảng lương'!$T$7) -> 90000 | H5: =IF($D5="","",$D5*'Bảng lương'!$U$7) -> 60000 | I5: =IF($D5="","",SUM(F5:H5)) -> 630000 | J5: =IF($D5="","",$D5*'Bảng lương'!$O$7) -> 1050000 | K5: =IF($D5="","",$D5*'Bảng lương'!$P$7) -> 180000 | L5: =IF($D5="","",$D5*'Bảng lương'!$Q$7) -> 60000 | M5: =IF($D5="","",SUM(J5:L5)) -> 1290000
A6: =IF('Mức lương'!A9="","",'Mức lương'!A9) -> I | B6: =IF('Mức lương'!B9="","",'Mức lương'!B9) -> BỘ PHẬN LÁI XE | D6: =IF($B6="","",IFERROR(IF(INDEX('Mức lương'!$I$8:$I$62,MATCH($B6,'Mức lương'!$B$8:$B$62,0))="","",INDEX('Mức lương'!$I$8:$I$62,MATCH($B6,'Mức lương'!$B$8:$B$62,0))),"")) | E6: =IF($D6="","",I6+M6) | F6: =IF($D6="","",$D6*'Bảng lương'!$S$7) | G6: =IF($D6="","",$D6*'Bảng lương'!$T$7) | H6: =IF($D6="","",$D6*'Bảng lương'!$U$7) | I6: =IF($D6="","",SUM(F6:H6)) | J6: =IF($D6="","",$D6*'Bảng lương'!$O$7) | K6: =IF($D6="","",$D6*'Bảng lương'!$P$7) | L6: =IF($D6="","",$D6*'Bảng lương'!$Q$7) | M6: =IF($D6="","",SUM(J6:L6))
A7: =IF('Mức lương'!A10="","",'Mức lương'!A10) -> 2 | B7: =IF('Mức lương'!B10="","",'Mức lương'!B10) -> NGUYỄN VĂN LỢI | D7: =IF($B7="","",IFERROR(IF(INDEX('Mức lương'!$I$8:$I$62,MATCH($B7,'Mức lương'!$B$8:$B$62,0))="","",INDEX('Mức lương'!$I$8:$I$62,MATCH($B7,'Mức lương'!$B$8:$B$62,0))),"")) -> 5500000 | E7: =IF($D7="","",I7+M7) -> 1760000 | F7: =IF($D7="","",$D7*'Bảng lương'!$S$7) -> 440000 | G7: =IF($D7="","",$D7*'Bảng lương'!$T$7) -> 82500 | H7: =IF($D7="","",$D7*'Bảng lương'!$U$7) -> 55000 | I7: =IF($D7="","",SUM(F7:H7)) -> 577500 | J7: =IF($D7="","",$D7*'Bảng lương'!$O$7) -> 962500 | K7: =IF($D7="","",$D7*'Bảng lương'!$P$7) -> 165000 | L7: =IF($D7="","",$D7*'Bảng lương'!$Q$7) -> 55000 | M7: =IF($D7="","",SUM(J7:L7)) -> 1182500
B8: TỔNG CỘNG | D8: =SUM(D5:D7) -> 11500000 | E8: =SUM(E5:E7) -> 3680000 | F8: =SUM(F5:F7) -> 920000 | G8: =SUM(G5:G7) -> 172500 | H8: =SUM(H5:H7) -> 115000 | I8: =SUM(I5:I7) -> 1207500 | J8: =SUM(J5:J7) -> 2012500 | K8: =SUM(K5:K7) -> 345000 | ... M8: =SUM(M5:M7) -> 2472500
G9: Trong đó: | H9: DN chịu 21.5 % | J9: =M8 -> 2472500
G10: Người lao động chịu 10.5% | J10: =I8 -> 1207500
G11: Tổng cộng | J11: =+J10+J9 -> 3680000 | K11: TPHCM, ngày …........... tháng …......... năm 2026
B12: GIÁM ĐỐC | E12: QUẢN LÝ | H12: PHÒNG KẾ TOÁN | K12: NGƯỜI LẬP

Sheet Thuế TNCN
A1: ="BẢNG TÍNH THUẾ TNCN THÁNG "&BCC!O4&"/"&BCC!O5 -> BẢNG TÍNH THUẾ TNCN THÁNG 10/2026
A2: STT | B2: Họ và tên | C2: MST | D2: Tiền Lương | E2: Thưởng (phụ cấp, kinh doanh, thưởng tết) | F2: Tạm ứng Tháng | G2: Thưởng | H2: Tổng Thu nhập | I2: Thu nhập miễn thuế | J2: Thu nhập chịu thuế | K2: Các khoản giảm trừ | N2: Các khoản không chịu thuế | Q2: Thu nhập tính thuế | R2: Thuế TNCN | S2: TNCN KTTN | T2: Tăng Ca chịu thuế | U2: Dòng Bảng lương (trợ giúp) | W2: THAM SỐ THUẾ
K3: Bản thân | L3: Người phụ thuộc | M3: Bảo hiểm | N3: Tăng Ca miễn thuế | O3: Điện thoại | P3: Tiền ăn | W3: Giảm trừ bản thân (đ/tháng) | X3: 15500000
A4: I. BAN GIÁM ĐỐC | W4: Giảm trừ mỗi người phụ thuộc (đ/tháng) | X4: 6200000
A5: =IF('Mức lương'!A8="","",'Mức lương'!A8) -> 1 | B5: =IF('Mức lương'!B8="","",'Mức lương'!B8) -> NGUYỄN KIM QUYẾT | D5: =IF($H5="","",INDEX('Bảng lương'!$D:$D,$U5)*INDEX('Bảng lương'!$AK:$AK,$U5)) -> 6000000 | E5: =IF($H5="","",(INDEX('Bảng lương'!$E:$E,$U5)+INDEX('Bảng lương'!$F:$F,$U5)+INDEX('Bảng lương'!$J:$J,$U5))*INDEX('Bảng lương'!$AK:$AK,$U5)+INDEX('Bảng lương'!$H:$H,$U5)+INDEX('Bảng lương'!$I:$I,$U5)) -> 6000000 | F5: =IF($H5="","",INDEX('Bảng lương'!$G:$G,$U5)) -> 0 | H5: =IF($U5="","",INDEX('Bảng lương'!$M:$M,$U5)) -> 12000000 | I5: =IF($H5="","",SUM(N5:P5)) -> #REF! | J5: =IF($H5="","",H5-I5) -> #REF! | K5: =IF($H5="","",$X$3) -> 15500000 | L5: =IF($H5="","",IFERROR(INDEX('Người phụ thuộc'!$C$2:$C$62,MATCH($B5,'Người phụ thuộc'!$B$2:$B$62,0)),0)) -> 0 | M5: =IF($H5="","",INDEX('Bảng lương'!$V:$V,$U5)) -> 630000 | N5: =IF($H5="","",INDEX('Bảng lương'!$AI:$AI,$U5)) -> #REF! | O5: =IF($H5="","",MIN(INDEX('Bảng lương'!$J:$J,$U5)*INDEX('Bảng lương'!$AK:$AK,$U5),#REF!)) -> #REF! | P5: =IF($H5="","",MIN(INDEX('Bảng lương'!$F:$F,$U5)*INDEX('Bảng lương'!$AK:$AK,$U5),$X$5)) -> 1000000 | Q5: =IF($H5="","",J5-K5-L5-M5) -> #REF! | R5: =IF(Q5="","",ROUND(MAX(0,IF(Q5<=10000000,5%*Q5,IF(Q5<=30000000,10%*(Q5-10000000)+500000,IF(Q5<=60000000,20%*(Q5-30000000)+2500000,IF(Q5<=100000000,30%*(Q5-60000000)+8500000,35%*(Q5-100000000)+20500000))))),0)) -> #REF! | T5: =IF($H5="","",INDEX('Bảng lương'!$AH:$AH,$U5)) -> #REF! | U5: =IF(B5="","",IFERROR(MATCH($B5,'Bảng lương'!$B:$B,0),"")) -> 10 | W5: Mức miễn thuế tiền ăn giữa ca/ăn trưa (đ/tháng, từ 1/7/2026) | X5: 1200000
A6: =IF('Mức lương'!A9="","",'Mức lương'!A9) -> I | B6: =IF('Mức lương'!B9="","",'Mức lương'!B9) -> BỘ PHẬN LÁI XE | D6: =IF($H6="","",INDEX('Bảng lương'!$D:$D,$U6)*INDEX('Bảng lương'!$AK:$AK,$U6)) | E6: =IF($H6="","",(INDEX('Bảng lương'!$E:$E,$U6)+INDEX('Bảng lương'!$F:$F,$U6)+INDEX('Bảng lương'!$J:$J,$U6))*INDEX('Bảng lương'!$AK:$AK,$U6)+INDEX('Bảng lương'!$H:$H,$U6)+INDEX('Bảng lương'!$I:$I,$U6)) | F6: =IF($H6="","",INDEX('Bảng lương'!$G:$G,$U6)) | H6: =IF($U6="","",INDEX('Bảng lương'!$M:$M,$U6)) | I6: =IF($H6="","",SUM(N6:P6)) | J6: =IF($H6="","",H6-I6) | K6: =IF($H6="","",$X$3) | L6: =IF($H6="","",IFERROR(INDEX('Người phụ thuộc'!$C$2:$C$62,MATCH($B6,'Người phụ thuộc'!$B$2:$B$62,0)),0)) | M6: =IF($H6="","",INDEX('Bảng lương'!$V:$V,$U6)) | N6: =IF($H6="","",INDEX('Bảng lương'!$AI:$AI,$U6)) | O6: =IF($H6="","",MIN(INDEX('Bảng lương'!$J:$J,$U6)*INDEX('Bảng lương'!$AK:$AK,$U6),#REF!)) | P6: =IF($H6="","",MIN(INDEX('Bảng lương'!$F:$F,$U6)*INDEX('Bảng lương'!$AK:$AK,$U6),$X$5)) | Q6: =IF($H6="","",J6-K6-L6-M6) | R6: =IF(Q6="","",ROUND(MAX(0,IF(Q6<=10000000,5%*Q6,IF(Q6<=30000000,10%*(Q6-10000000)+500000,IF(Q6<=60000000,20%*(Q6-30000000)+2500000,IF(Q6<=100000000,30%*(Q6-60000000)+8500000,35%*(Q6-100000000)+20500000))))),0)) | T6: =IF($H6="","",INDEX('Bảng lương'!$AH:$AH,$U6)) | U6: =IF(B6="","",IFERROR(MATCH($B6,'Bảng lương'!$B:$B,0),"")) -> 11
A7: =IF('Mức lương'!A10="","",'Mức lương'!A10) -> 2 | B7: =IF('Mức lương'!B10="","",'Mức lương'!B10) -> NGUYỄN VĂN LỢI | D7: =IF($H7="","",INDEX('Bảng lương'!$D:$D,$U7)*INDEX('Bảng lương'!$AK:$AK,$U7)) -> 3596153.8 | E7: =IF($H7="","",(INDEX('Bảng lương'!$E:$E,$U7)+INDEX('Bảng lương'!$F:$F,$U7)+INDEX('Bảng lương'!$J:$J,$U7))*INDEX('Bảng lương'!$AK:$AK,$U7)+INDEX('Bảng lương'!$H:$H,$U7)+INDEX('Bảng lương'!$I:$I,$U7)) -> 12833166 | F7: =IF($H7="","",INDEX('Bảng lương'!$G:$G,$U7)) -> 10000000 | H7: =IF($U7="","",INDEX('Bảng lương'!$M:$M,$U7)) -> 16429320 | I7: =IF($H7="","",SUM(N7:P7)) -> #REF! | J7: =IF($H7="","",H7-I7) -> #REF! | K7: =IF($H7="","",$X$3) -> 15500000 | L7: =IF($H7="","",IFERROR(INDEX('Người phụ thuộc'!$C$2:$C$62,MATCH($B7,'Người phụ thuộc'!$B$2:$B$62,0)),0)) -> 0 | M7: =IF($H7="","",INDEX('Bảng lương'!$V:$V,$U7)) -> 577500 | N7: =IF($H7="","",INDEX('Bảng lương'!$AI:$AI,$U7)) -> #REF! | O7: =IF($H7="","",MIN(INDEX('Bảng lương'!$J:$J,$U7)*INDEX('Bảng lương'!$AK:$AK,$U7),#REF!)) -> #REF! | P7: =IF($H7="","",MIN(INDEX('Bảng lương'!$F:$F,$U7)*INDEX('Bảng lương'!$AK:$AK,$U7),$X$5)) -> 653846.15 | Q7: =IF($H7="","",J7-K7-L7-M7) -> #REF! | R7: =IF(Q7="","",ROUND(MAX(0,IF(Q7<=10000000,5%*Q7,IF(Q7<=30000000,10%*(Q7-10000000)+500000,IF(Q7<=60000000,20%*(Q7-30000000)+2500000,IF(Q7<=100000000,30%*(Q7-60000000)+8500000,35%*(Q7-100000000)+20500000))))),0)) -> #REF! | T7: =IF($H7="","",INDEX('Bảng lương'!$AH:$AH,$U7)) -> #REF! | U7: =IF(B7="","",IFERROR(MATCH($B7,'Bảng lương'!$B:$B,0),"")) -> 12
B8: TỔNG CỘNG | D8: =SUM(D5:D7) -> 9596153.8 | E8: =SUM(E5:E7) -> 18833166 | F8: =SUM(F5:F7) -> 10000000 | G8: =SUM(G5:G7) -> 0 | H8: =SUM(H5:H7) -> 28429320 | I8: =SUM(I5:I7) -> #REF! | J8: =SUM(J5:J7) -> #REF! | K8: =SUM(K5:K7) -> 31000000 | ... R8: =SUM(R5:R7) -> #REF! | T8: =SUM(T5:T7) -> #REF!
B11: GIÁM ĐỐC | E11: QUẢN LÝ | I11: PHÒNG KẾ TOÁN | M11: NGƯỜI LẬP

Sheet Bảng lương
A1: CÔNG TY ….................
A2: Địa chỉ: ….............
A3: ="BẢNG TÍNH - THANH TOÁN TIỀN LƯƠNG THÁNG "&BCC!O4&"/"&BCC!O5 -> BẢNG TÍNH - THANH TOÁN TIỀN LƯƠNG THÁNG 10/2026
P4: =BCC!$AJ$5 -> 26
A5: STT | B5: Họ và tên | C5: Chức vụ | D5: Lương Chính | E5: Phụ cấp | K5: Công Thực tế | L5: Công Chuẩn | M5: Tổng Lương Thực Tế | N5: Lương đóng BH | O5: Trích vào Chi phí Doanh nghiệp | S5: Trích vào Lương nhân viên | W5: Tổng trừ lương | Z5: Thực lĩnh | AA5: Giờ TC 150% | AB5: Giờ TC 200% | AC5: Giờ TC 300% | AD5: Tổng giờ tăng ca | AE5: Đơn giá TC (đ/giờ) | AF5: Tiền tăng ca | AG5: Đơn giá ngày thường (đ/giờ) | AH5: TC chịu thuế | AI5: TC miễn thuế | AJ5: Ghi Chú | AK5: Hệ số công (Công TT/Công chuẩn, tối đa 1)
E6: Trách nhiệm | F6: Tiền ăn ttrưa | G6: Tạm ứng | H6: Định mức Lương chuyến LX, Định mức lương KD & sale | I6: Thưởng | J6: Điện thoại | O6: BHXH (17.5%) | P6: BHYT (3%) | Q6: BHTN (1%) | R6: Cộng 20,5% | S6: BHXH (8%) | T6: BHYT (1,5%) | U6: BHTN (1%) | V6: Cộng 10,5% | W6: Trừ Thuế TNCN | X6: Các Khoản trừ | Y6: Công đoàn
O7: 0.175 | P7: 0.03 | Q7: 0.01 | R7: =SUM(O7:Q7) -> 0.215 | S7: 0.08 | T7: 0.015 | U7: 0.01 | V7: 0.105
B8: 1 | C8: 2 | D8: 3 | E8: 4 | F8: 5 | G8: 6 | H8: 7 | I8: 8 | J8: 9 | K8: 10 | L8: 11 | M8: 12 | N8: 13 | O8: 14 | P8: 15 | Q8: 16 | R8: 17 | S8: 18 | T8: 19 | U8: 20 | V8: 21 | W8: 22 | X8: 23 | Y8: 24 | Z8: 25 | AA8: 26 | AB8: 27 | AC8: 28 | AD8: 29 | AE8: 30 | AF8: 31 | AG8: 32 | AH8: 33 | AI8: 34 | AK8: 35
A9: I. BAN GIÁM ĐỐC
A10: =IF(ISNUMBER(D10),COUNT($D$10:D10),"") -> 1 | B10: =IF('Mức lương'!B8="","",'Mức lương'!B8) -> NGUYỄN KIM QUYẾT | C10: =IF(B10="","",IFERROR(IF(INDEX('Mức lương'!$C$8:$C$62,MATCH($B10,'Mức lương'!$B$8:$B$62,0))="","",INDEX('Mức lương'!$C$8:$C$62,MATCH($B10,'Mức lương'!$B$8:$B$62,0))),"")) -> Giám Đốc | D10: =IF($B10="","",IFERROR(IF(INDEX('Mức lương'!$D$8:$D$62,MATCH($B10,'Mức lương'!$B$8:$B$62,0))="","",INDEX('Mức lương'!$D$8:$D$62,MATCH($B10,'Mức lương'!$B$8:$B$62,0))),"")) -> 6000000 | E10: =IF($D10="","",IFERROR(INDEX('Mức lương'!$F$8:$F$62,MATCH($B10,'Mức lương'!$B$8:$B$62,0))+0,0)) -> 3000000 | F10: =IF($D10="","",IFERROR(INDEX('Mức lương'!$G$8:$G$62,MATCH($B10,'Mức lương'!$B$8:$B$62,0))+0,0)) -> 1000000 | G10: =IF($D10="","",IFERROR(INDEX('Thưởng KPI+Định mức'!$D$5:$D$62,MATCH($B10,'Thưởng KPI+Định mức'!$B$5:$B$62,0))+0,0)) -> 0 | H10: =IF($D10="","",IFERROR(INDEX('Thưởng KPI+Định mức'!$E$5:$E$62,MATCH($B10,'Thưởng KPI+Định mức'!$B$5:$B$62,0))+0,0)+IFERROR(INDEX('Thưởng KPI+Định mức'!$F$5:$F$62,MATCH($B10,'Thưởng KPI+Định mức'!$B$5:$B$62,0))+0,0)) -> 0 | J10: =IF($D10="","",IFERROR(INDEX('Mức lương'!$E$8:$E$62,MATCH($B10,'Mức lương'!$B$8:$B$62,0))+0,0)) -> 2000000 | K10: =IF($D10="","",IFERROR(INDEX(BCC!$AJ$9:$AJ$131,MATCH($B10,BCC!$B$9:$B$131,0))+SUM(INDEX(BCC!$AL$9:$AP$131,MATCH($B10,BCC!$B$9:$B$131,0),0)),0)) -> 27 | L10: =IF($D10="","",BCC!$AJ$5) -> 26 | M10: =IF($D10="","",ROUND((D10+E10+F10+J10)*AK10+AF10+H10+N(I10),0)) -> 12000000 | N10: =IF($D10="","",IFERROR(INDEX(BHXH!$D$5:$D$7,MATCH($B10,BHXH!$B$5:$B$7,0))+0,0)) -> 6000000 | O10: =IF($D10="","",$N10*O$7) -> 1050000 | P10: =IF($D10="","",$N10*P$7) -> 180000 | Q10: =IF($D10="","",$N10*Q$7) -> 60000 | R10: =IF($D10="","",SUM(O10:Q10)) -> 1290000 | S10: =IF($D10="","",$N10*S$7) -> 480000 | T10: =IF($D10="","",$N10*T$7) -> 90000 | U10: =IF($D10="","",$N10*U$7) -> 60000 | V10: =IF($D10="","",SUM(S10:U10)) -> 630000 | W10: =IF($D10="","",IFERROR(INDEX('Thuế TNCN'!$R$5:$R$62,MATCH($B10,'Thuế TNCN'!$B$5:$B$62,0))+0,0)) -> 0 | X10: =IF($D10="","",G10) -> 0 | Z10: =IF($D10="","",M10-V10-W10-X10-N(Y10)) -> 11370000 | AA10: =IF($D10="","",IFERROR(INDEX(BCC!$AQ$9:$AQ$131,MATCH($B10,BCC!$B$9:$B$131,0)),0)) -> 0 | AB10: =IF($D10="","",IFERROR(INDEX(BCC!$AR$9:$AR$131,MATCH($B10,BCC!$B$9:$B$131,0)),0)) -> 0 | AC10: =IF($D10="","",IFERROR(INDEX(BCC!$AS$9:$AS$131,MATCH($B10,BCC!$B$9:$B$131,0)),0)) -> 0 | AD10: =IF($D10="","",SUM(AA10:AC10)) -> 0 | AE10: =IF($D10="","",IF(AND(C10="Nhân Viên bốc xếp",AD10>0),(AA10*1.5+AB10*2+AC10*3)*AG10/AD10,0)) -> 0 | AF10: =IF($D10="","",ROUND(AD10*AE10,0)) -> 0 | AG10: =IF($D10="","",IF(L10=0,0,D10/(L10*8))) -> 28846.154 | AH10: =IF($D10="","",AF10-AI10) -> #REF! | AI10: =IF($D10="","",ROUND(AF10*'Thuế TNCN'!#REF!,0)) -> #REF! | AK10: =IF($D10="","",IF(L10=0,0,MIN(K10,L10)/L10)) -> 1
A11: =IF(ISNUMBER(D11),COUNT($D$10:D11),"") | B11: =IF('Mức lương'!B9="","",'Mức lương'!B9) -> BỘ PHẬN LÁI XE | C11: =IF(B11="","",IFERROR(IF(INDEX('Mức lương'!$C$8:$C$62,MATCH($B11,'Mức lương'!$B$8:$B$62,0))="","",INDEX('Mức lương'!$C$8:$C$62,MATCH($B11,'Mức lương'!$B$8:$B$62,0))),"")) | D11: =IF($B11="","",IFERROR(IF(INDEX('Mức lương'!$D$8:$D$62,MATCH($B11,'Mức lương'!$B$8:$B$62,0))="","",INDEX('Mức lương'!$D$8:$D$62,MATCH($B11,'Mức lương'!$B$8:$B$62,0))),"")) | E11: =IF($D11="","",IFERROR(INDEX('Mức lương'!$F$8:$F$62,MATCH($B11,'Mức lương'!$B$8:$B$62,0))+0,0)) | F11: =IF($D11="","",IFERROR(INDEX('Mức lương'!$G$8:$G$62,MATCH($B11,'Mức lương'!$B$8:$B$62,0))+0,0)) | G11: =IF($D11="","",IFERROR(INDEX('Thưởng KPI+Định mức'!$D$5:$D$62,MATCH($B11,'Thưởng KPI+Định mức'!$B$5:$B$62,0))+0,0)) | H11: =IF($D11="","",IFERROR(INDEX('Thưởng KPI+Định mức'!$E$5:$E$62,MATCH($B11,'Thưởng KPI+Định mức'!$B$5:$B$62,0))+0,0)+IFERROR(INDEX('Thưởng KPI+Định mức'!$F$5:$F$62,MATCH($B11,'Thưởng KPI+Định mức'!$B$5:$B$62,0))+0,0)) | J11: =IF($D11="","",IFERROR(INDEX('Mức lương'!$E$8:$E$62,MATCH($B11,'Mức lương'!$B$8:$B$62,0))+0,0)) | K11: =IF($D11="","",IFERROR(INDEX(BCC!$AJ$9:$AJ$131,MATCH($B11,BCC!$B$9:$B$131,0))+SUM(INDEX(BCC!$AL$9:$AP$131,MATCH($B11,BCC!$B$9:$B$131,0),0)),0)) | L11: =IF($D11="","",BCC!$AJ$5) | M11: =IF($D11="","",ROUND((D11+E11+F11+J11)*AK11+AF11+H11+N(I11),0)) | N11: =IF($D11="","",IFERROR(INDEX(BHXH!$D$5:$D$7,MATCH($B11,BHXH!$B$5:$B$7,0))+0,0)) | O11: =IF($D11="","",$N11*O$7) | P11: =IF($D11="","",$N11*P$7) | Q11: =IF($D11="","",$N11*Q$7) | R11: =IF($D11="","",SUM(O11:Q11)) | S11: =IF($D11="","",$N11*S$7) | T11: =IF($D11="","",$N11*T$7) | U11: =IF($D11="","",$N11*U$7) | V11: =IF($D11="","",SUM(S11:U11)) | W11: =IF($D11="","",IFERROR(INDEX('Thuế TNCN'!$R$5:$R$62,MATCH($B11,'Thuế TNCN'!$B$5:$B$62,0))+0,0)) | X11: =IF($D11="","",G11) | Z11: =IF($D11="","",M11-V11-W11-X11-N(Y11)) | AA11: =IF($D11="","",IFERROR(INDEX(BCC!$AQ$9:$AQ$131,MATCH($B11,BCC!$B$9:$B$131,0)),0)) | AB11: =IF($D11="","",IFERROR(INDEX(BCC!$AR$9:$AR$131,MATCH($B11,BCC!$B$9:$B$131,0)),0)) | AC11: =IF($D11="","",IFERROR(INDEX(BCC!$AS$9:$AS$131,MATCH($B11,BCC!$B$9:$B$131,0)),0)) | AD11: =IF($D11="","",SUM(AA11:AC11)) | AE11: =IF($D11="","",IF(AND(C11="Nhân Viên bốc xếp",AD11>0),(AA11*1.5+AB11*2+AC11*3)*AG11/AD11,0)) | AF11: =IF($D11="","",ROUND(AD11*AE11,0)) | AG11: =IF($D11="","",IF(L11=0,0,D11/(L11*8))) | AH11: =IF($D11="","",AF11-AI11) | AI11: =IF($D11="","",ROUND(AF11*'Thuế TNCN'!#REF!,0)) | AK11: =IF($D11="","",IF(L11=0,0,MIN(K11,L11)/L11))
A12: =IF(ISNUMBER(D12),COUNT($D$10:D12),"") -> 2 | B12: =IF('Mức lương'!B10="","",'Mức lương'!B10) -> NGUYỄN VĂN LỢI | C12: =IF(B12="","",IFERROR(IF(INDEX('Mức lương'!$C$8:$C$62,MATCH($B12,'Mức lương'!$B$8:$B$62,0))="","",INDEX('Mức lương'!$C$8:$C$62,MATCH($B12,'Mức lương'!$B$8:$B$62,0))),"")) -> Tài xế xe tải | D12: =IF($B12="","",IFERROR(IF(INDEX('Mức lương'!$D$8:$D$62,MATCH($B12,'Mức lương'!$B$8:$B$62,0))="","",INDEX('Mức lương'!$D$8:$D$62,MATCH($B12,'Mức lương'!$B$8:$B$62,0))),"")) -> 5500000 | E12: =IF($D12="","",IFERROR(INDEX('Mức lương'!$F$8:$F$62,MATCH($B12,'Mức lương'!$B$8:$B$62,0))+0,0)) -> 500000 | F12: =IF($D12="","",IFERROR(INDEX('Mức lương'!$G$8:$G$62,MATCH($B12,'Mức lương'!$B$8:$B$62,0))+0,0)) -> 1000000 | G12: =IF($D12="","",IFERROR(INDEX('Thưởng KPI+Định mức'!$D$5:$D$62,MATCH($B12,'Thưởng KPI+Định mức'!$B$5:$B$62,0))+0,0)) -> 10000000 | H12: =IF($D12="","",IFERROR(INDEX('Thưởng KPI+Định mức'!$E$5:$E$62,MATCH($B12,'Thưởng KPI+Định mức'!$B$5:$B$62,0))+0,0)+IFERROR(INDEX('Thưởng KPI+Định mức'!$F$5:$F$62,MATCH($B12,'Thưởng KPI+Định mức'!$B$5:$B$62,0))+0,0)) -> 11525473 | J12: =IF($D12="","",IFERROR(INDEX('Mức lương'!$E$8:$E$62,MATCH($B12,'Mức lương'!$B$8:$B$62,0))+0,0)) -> 500000 | K12: =IF($D12="","",IFERROR(INDEX(BCC!$AJ$9:$AJ$131,MATCH($B12,BCC!$B$9:$B$131,0))+SUM(INDEX(BCC!$AL$9:$AP$131,MATCH($B12,BCC!$B$9:$B$131,0),0)),0)) -> 17 | L12: =IF($D12="","",BCC!$AJ$5) -> 26 | M12: =IF($D12="","",ROUND((D12+E12+F12+J12)*AK12+AF12+H12+N(I12),0)) -> 16429320 | N12: =IF($D12="","",IFERROR(INDEX(BHXH!$D$5:$D$7,MATCH($B12,BHXH!$B$5:$B$7,0))+0,0)) -> 5500000 | O12: =IF($D12="","",$N12*O$7) -> 962500 | P12: =IF($D12="","",$N12*P$7) -> 165000 | Q12: =IF($D12="","",$N12*Q$7) -> 55000 | R12: =IF($D12="","",SUM(O12:Q12)) -> 1182500 | S12: =IF($D12="","",$N12*S$7) -> 440000 | T12: =IF($D12="","",$N12*T$7) -> 82500 | U12: =IF($D12="","",$N12*U$7) -> 55000 | V12: =IF($D12="","",SUM(S12:U12)) -> 577500 | W12: =IF($D12="","",IFERROR(INDEX('Thuế TNCN'!$R$5:$R$62,MATCH($B12,'Thuế TNCN'!$B$5:$B$62,0))+0,0)) -> 0 | X12: =IF($D12="","",G12) -> 10000000 | Z12: =IF($D12="","",M12-V12-W12-X12-N(Y12)) -> 5851820 | AA12: =IF($D12="","",IFERROR(INDEX(BCC!$AQ$9:$AQ$131,MATCH($B12,BCC!$B$9:$B$131,0)),0)) -> 0 | AB12: =IF($D12="","",IFERROR(INDEX(BCC!$AR$9:$AR$131,MATCH($B12,BCC!$B$9:$B$131,0)),0)) -> 0 | AC12: =IF($D12="","",IFERROR(INDEX(BCC!$AS$9:$AS$131,MATCH($B12,BCC!$B$9:$B$131,0)),0)) -> 0 | AD12: =IF($D12="","",SUM(AA12:AC12)) -> 0 | AE12: =IF($D12="","",IF(AND(C12="Nhân Viên bốc xếp",AD12>0),(AA12*1.5+AB12*2+AC12*3)*AG12/AD12,0)) -> 0 | AF12: =IF($D12="","",ROUND(AD12*AE12,0)) -> 0 | AG12: =IF($D12="","",IF(L12=0,0,D12/(L12*8))) -> 26442.308 | AH12: =IF($D12="","",AF12-AI12) -> #REF! | AI12: =IF($D12="","",ROUND(AF12*'Thuế TNCN'!#REF!,0)) -> #REF! | AK12: =IF($D12="","",IF(L12=0,0,MIN(K12,L12)/L12)) -> 0.65384615
B13: TỔNG CỘNG | D13: =SUBTOTAL(9,D10:D12) -> 11500000 | E13: =SUBTOTAL(9,E10:E12) -> 3500000 | F13: =SUBTOTAL(9,F10:F12) -> 2000000 | G13: =SUBTOTAL(9,G10:G12) -> 10000000 | H13: =SUBTOTAL(9,H10:H12) -> 11525473 | I13: =SUBTOTAL(9,I10:I12) -> 0 | J13: =SUBTOTAL(9,J10:J12) -> 2500000 | K13: =SUBTOTAL(9,K10:K12) -> 44 | M13: =SUBTOTAL(9,M10:M12) -> 28429320 | N13: =SUBTOTAL(9,N10:N12) -> 11500000 | O13: =SUBTOTAL(9,O10:O12) -> 2012500 | P13: =SUBTOTAL(9,P10:P12) -> 345000 | Q13: =SUBTOTAL(9,Q10:Q12) -> 115000 | R13: =SUBTOTAL(9,R10:R12) -> 2472500 | S13: =SUBTOTAL(9,S10:S12) -> 920000 | T13: =SUBTOTAL(9,T10:T12) -> 172500 | ... AD13: =SUBTOTAL(9,AD10:AD12) -> 0 | AF13: =SUBTOTAL(9,AF10:AF12) -> 0 | AH13: =SUBTOTAL(9,AH10:AH12) -> #REF! | AI13: =SUBTOTAL(9,AI10:AI12) -> #REF!
U14: TP HCM, ngày 0…. tháng 0…. năm 202….
B15: NGƯỜI LẬP | G15: PHÒNG KẾ TOÁN | N15: QUẢN LÝ | U15: GIÁM ĐỐC

Sheet Phiếu lương
A1: CÔNG TY TNHH VẬN TẢI ĐẠI LỘ XANH
A2: Địa chỉ: Số nhà 306, Đường 303, Thôn Giã Bàng, Xã Tề Lỗ, Tỉnh Phú Thọ
A3: ="PHIẾU LƯƠNG THÁNG "&BCC!O4&"/"&BCC!O5 -> PHIẾU LƯƠNG THÁNG 10/2026
A4: Họ và tên | B4: NGUYỄN KIM QUYẾT | D4: Công chuẩn | E4: =IF($B$4="","",IFERROR(INDEX('Bảng lương'!$L$10:$L$12,MATCH($B$4,'Bảng lương'!$B$10:$B$12,0)),0)) -> 26
A5: Chức danh | B5: =IF($B$4="","",IFERROR(INDEX('Bảng lương'!$C$10:$C$12,MATCH($B$4,'Bảng lương'!$B$10:$B$12,0)),"")) -> Giám Đốc | D5: Lương đóng BH | E5: =IF($B$4="","",IFERROR(INDEX('Bảng lương'!$N$10:$N$12,MATCH($B$4,'Bảng lương'!$B$10:$B$12,0)),0)) -> 6000000
D6: Tổng công Thực tế | E6: =IF($B$4="","",IFERROR(INDEX('Bảng lương'!$K$10:$K$12,MATCH($B$4,'Bảng lương'!$B$10:$B$12,0)),0)) -> 27
A8: STT | B8: CÁC KHOẢN THU NHẬP | C8: SỐ TIỀN | D8: STT | E8: CÁC KHOẢN TRỪ | F8: SỐ TIỀN
A9: 1 | B9: Lương theo công | C9: =IF($B$4="","",IFERROR(INDEX('Bảng lương'!$D$10:$D$12,MATCH($B$4,'Bảng lương'!$B$10:$B$12,0))*INDEX('Bảng lương'!$AK$10:$AK$12,MATCH($B$4,'Bảng lương'!$B$10:$B$12,0)),0)) -> 6000000 | D9: 1 | E9: BHXH (8%) | F9: =IF($B$4="","",IFERROR(INDEX('Bảng lương'!$S$10:$S$12,MATCH($B$4,'Bảng lương'!$B$10:$B$12,0)),0)) -> 480000
A10: 2 | B10: Phụ cấp trách nhiệm | C10: =IF($B$4="","",IFERROR(INDEX('Bảng lương'!$E$10:$E$12,MATCH($B$4,'Bảng lương'!$B$10:$B$12,0))*INDEX('Bảng lương'!$AK$10:$AK$12,MATCH($B$4,'Bảng lương'!$B$10:$B$12,0)),0)) -> 3000000 | D10: 2 | E10: BHYT (1,5%) | F10: =IF($B$4="","",IFERROR(INDEX('Bảng lương'!$T$10:$T$12,MATCH($B$4,'Bảng lương'!$B$10:$B$12,0)),0)) -> 90000
A11: 3 | B11: Phụ cấp ăn trưa | C11: =IF($B$4="","",IFERROR(INDEX('Bảng lương'!$F$10:$F$12,MATCH($B$4,'Bảng lương'!$B$10:$B$12,0))*INDEX('Bảng lương'!$AK$10:$AK$12,MATCH($B$4,'Bảng lương'!$B$10:$B$12,0)),0)) -> 1000000 | D11: 3 | E11: BHTN (1%) | F11: =IF($B$4="","",IFERROR(INDEX('Bảng lương'!$U$10:$U$12,MATCH($B$4,'Bảng lương'!$B$10:$B$12,0)),0)) -> 60000
A12: 4 | B12: Phụ cấp điện thoại | C12: =IF($B$4="","",IFERROR(INDEX('Bảng lương'!$J$10:$J$12,MATCH($B$4,'Bảng lương'!$B$10:$B$12,0))*INDEX('Bảng lương'!$AK$10:$AK$12,MATCH($B$4,'Bảng lương'!$B$10:$B$12,0)),0)) -> 2000000 | D12: 4 | E12: Thuế TNCN | F12: =IF($B$4="","",IFERROR(INDEX('Bảng lương'!$W$10:$W$12,MATCH($B$4,'Bảng lương'!$B$10:$B$12,0)),0)) -> 0
A13: 5 | B13: Hiệu suất cv / Định mức / Thưởng | C13: =IF($B$4="","",IFERROR(INDEX('Bảng lương'!$H$10:$H$12,MATCH($B$4,'Bảng lương'!$B$10:$B$12,0))+N(INDEX('Bảng lương'!$I$10:$I$12,MATCH($B$4,'Bảng lương'!$B$10:$B$12,0))),0)) -> 0 | D13: 5 | E13: Tạm ứng / Khác | F13: =IF($B$4="","",IFERROR(INDEX('Bảng lương'!$X$10:$X$12,MATCH($B$4,'Bảng lương'!$B$10:$B$12,0))+N(INDEX('Bảng lương'!$Y$10:$Y$12,MATCH($B$4,'Bảng lương'!$B$10:$B$12,0))),0)) -> 0
A14: 6 | B14: Tăng ca (phần chịu thuế) | C14: =IF($B$4="","",IFERROR(INDEX('Bảng lương'!$AH$10:$AH$12,MATCH($B$4,'Bảng lương'!$B$10:$B$12,0)),0)) -> 0
A15: (A) | B15: TỔNG THU NHẬP | C15: =IF($B$4="","",SUM(C9:C14)) -> 12000000 | D15: (B) | E15: TỔNG CÁC KHOẢN TRỪ | F15: =IF($B$4="","",SUM(F9:F13)) -> 630000
A16: Tổng cộng: = A-B + C | D16: (C) | E16: Tổng Tăng ca miễn thuế | F16: =IF($B$4="","",IFERROR(INDEX('Bảng lương'!$AI$10:$AI$12,MATCH($B$4,'Bảng lương'!$B$10:$B$12,0)),0)) -> 0
A17: THỰC LĨNH (Tổng thu nhập - Tổng khoản trừ) | D17: =IF($B$4="","",C15-F15+F16) -> 11370000
B19: Người lập phiếu | E19: Người nhận tiền

Sheet DS số TKNH
A1: DANH SÁCH SỐ TÀI KHOẢN NGÂN HÀNG & HỒ SƠ NHÂN VIÊN
A2: STT | B2: TÊN NV | C2: CHỨC DANH | D2: Mã NV | E2: Ngày sinh | F2: Giới tính | G2: Số CCCD | H2: Ngày cấp CCCD | I2: Nơi cấp CCCD | J2: Địa chỉ thường trú | K2: Địa chỉ hiện tại | L2: Số điện thoại | M2: Ngày vào làm | N2: Loại hợp đồng | O2: Số tài khoản | P2: Ngân hàng | Q2: Chi nhánh | R2: Note
A3: =IF('Mức lương'!A8="","",'Mức lương'!A8) -> 1 | B3: =IF('Mức lương'!B8="","",'Mức lương'!B8) -> NGUYỄN KIM QUYẾT | C3: =IF('Mức lương'!C8="","",'Mức lương'!C8) -> Giám Đốc | D3: =IF(ISNUMBER(A3),"NV"&TEXT(A3,"00"),"") -> NV01 | I3: Cục Cảnh sát QLHC về TTXH | N3: Không xác định thời hạn
A4: =IF('Mức lương'!A9="","",'Mức lương'!A9) -> I | B4: =IF('Mức lương'!B9="","",'Mức lương'!B9) -> BỘ PHẬN LÁI XE | C4: =IF('Mức lương'!C9="","",'Mức lương'!C9) | D4: =IF(ISNUMBER(A4),"NV"&TEXT(A4,"00"),"") | I4: Cục Cảnh sát QLHC về TTXH | N4: Không xác định thời hạn
A5: =IF('Mức lương'!A10="","",'Mức lương'!A10) -> 2 | B5: =IF('Mức lương'!B10="","",'Mức lương'!B10) -> NGUYỄN VĂN LỢI | C5: =IF('Mức lương'!C10="","",'Mức lương'!C10) -> Tài xế xe tải | D5: =IF(ISNUMBER(A5),"NV"&TEXT(A5,"00"),"") -> NV02 | I5: Cục Cảnh sát QLHC về TTXH | M5: 46296 | N5: Không xác định thời hạn

Sheet HĐ LAO ĐỘNG VP
A2: CÔNG TY TNHH ….. | C2: CỘNG HÒA XÃ HỘI CHỦ NGHĨA VIỆT NAM | H2: Nhập Mã NV để tự động điền hợp đồng:
C3: Độc lập - Tự do - Hạnh phúc | H3: =IF($I$2="","",IFERROR("Đã chọn: "&$I$5&" - "&$I$6,"⚠ Không tìm thấy Mã NV trong sheet DS số TKNH"))
A4: Số: …/HĐLĐ-… | C4: ……, ngày … tháng …. năm 202… | H4: BẢNG TRA CỨU (ẨN, hàng 5-18) - KHÔNG XÓA
H5: Mã NV | I5: =$I$2 -> 0
A6: HỢP ĐỒNG LAO ĐỘNG | H6: Tên NV | I6: =IFERROR(INDEX('DS số TKNH'!$B:$B,MATCH($I$2,'DS số TKNH'!$D:$D,0)),"")
H7: Chức danh | I7: =IFERROR(INDEX('DS số TKNH'!$C:$C,MATCH($I$2,'DS số TKNH'!$D:$D,0)),"")
A8: Chúng tôi, một bên là: | H8: Ngày sinh | I8: =IFERROR(INDEX('DS số TKNH'!$E:$E,MATCH($I$2,'DS số TKNH'!$D:$D,0)),"")
A9: Ông: … | E9: Quốc tịch: Việt Nam | H9: Giới tính | I9: =IFERROR(INDEX('DS số TKNH'!$F:$F,MATCH($I$2,'DS số TKNH'!$D:$D,0)),"")
A10: Chức vụ: … | H10: Số CCCD | I10: =IFERROR(INDEX('DS số TKNH'!$G:$G,MATCH($I$2,'DS số TKNH'!$D:$D,0)),"")
A11: Đại diện cho (1): Công Ty TNHH …. | H11: Ngày cấp CCCD | I11: =IFERROR(INDEX('DS số TKNH'!$H:$H,MATCH($I$2,'DS số TKNH'!$D:$D,0)),"")
A12: Địa chỉ: …. | H12: Nơi cấp CCCD | I12: =IFERROR(INDEX('DS số TKNH'!$I:$I,MATCH($I$2,'DS số TKNH'!$D:$D,0)),"")
A13: Và một bên là: | H13: Địa chỉ thường trú | I13: =IFERROR(INDEX('DS số TKNH'!$J:$J,MATCH($I$2,'DS số TKNH'!$D:$D,0)),"")
A14: ="Ông (bà): "&IF($I$6="","…..",$I$6) -> Ông (bà): ….. | E14: Quốc tịch: Việt Nam | H14: Địa chỉ hiện tại | I14: =IFERROR(INDEX('DS số TKNH'!$K:$K,MATCH($I$2,'DS số TKNH'!$D:$D,0)),"")
A15: ="Chức vụ (2): "&IF($I$7="","….",$I$7) -> Chức vụ (2): …. | H15: Số điện thoại | I15: =IFERROR(INDEX('DS số TKNH'!$L:$L,MATCH($I$2,'DS số TKNH'!$D:$D,0)),"")
A16: ="Sinh năm (3): "&IF($I$8="","…..",TEXT($I$8,"dd/mm/yyyy")) -> Sinh năm (3): ….. | H16: Ngày vào làm | I16: =IFERROR(INDEX('DS số TKNH'!$M:$M,MATCH($I$2,'DS số TKNH'!$D:$D,0)),"")
A17: ="CMND/CCCD: "&IF($I$10="","….",$I$10)&IF($I$11="",""," Ngày cấp: "&TEXT($I$11,"dd/mm/yyyy"))&IF($I$12="",""," Nơi cấp: "&$I$12) -> CMND/CCCD: …. | C17: Ngày cấp: ….. Nơi cấp: ….. | H17: Loại hợp đồng | I17: =IFERROR(INDEX('DS số TKNH'!$N:$N,MATCH($I$2,'DS số TKNH'!$D:$D,0)),"")
A18: ="Địa chỉ thường trú: "&IF($I$13="","….",$I$13) -> Địa chỉ thường trú: …. | H18: Mức lương | I18: =IFERROR(INDEX('Mức lương'!$D:$D,MATCH($I$6,'Mức lương'!$B:$B,0)),"")
A19: ="Địa chỉ cư trú: "&IF($I$14="","……",$I$14) -> Địa chỉ cư trú: ……
A21: Thỏa thuận ký kết hợp đồng lao động (“HĐLĐ”) và cam kết làm đúng những điều khoản sau đây:
A22: Điều 1: Thời hạn và công việc hợp đồng
A23: ="Loại hợp đồng lao động (3): Hợp đồng "&IF($I$17="","không xác định thời hạn",LOWER($I$17)) -> Loại hợp đồng lao động (3): Hợp đồng không xác định thời hạn
A24: ="- Hợp đồng có hiệu lực từ ngày: "&IF($I$16="","………",TEXT($I$16,"dd/mm/yyyy")) -> - Hợp đồng có hiệu lực từ ngày: ………
A25: - Địa điểm làm việc (4): ….. và các địa điểm khác theo yêu cầu.
A26: - Công việc phải làm (5):
A27: ü Theo bản Mô tả công việc;
A28: ü Người lao động (“NLĐ”) thực hiện công việc theo đúng chức danh chuyên môn dưới sự quản lý, điều hành của Người sử dụng lao động (“NSDLĐ”) (và các cá nhân được bổ nhiệm và ủy quyền của NSDLĐ). Đồng thời phối hợp với các bộ phận khác trong Công ty để phát huy hiệu quả công việc.
A30: Điều 2: THỜI GIỜ LÀM VIỆC VÀ NGHỈ NGƠI
A31: - Thời gian làm việc (6): 08 giờ/ngày, 48 giờ/tuần
A32: ü Buổi sáng: từ 07h00 đến 11h30
A33: ü Buổi chiều: từ 13h00 đến 16h30
A34: Thời gian cụ thể theo quy định trong Nội quy, Quy chế nội bộ của Công ty và các quyết định của Công ty trong từng giai đoạn cụ thể.
A35: - Được cấp phát những công cụ - dụng cụ, thiết bị làm việc gồm: NLĐ được trang bị bảo hộ lao động cần thiết, phù hợp với nội dung và tính chất công việc. Khi xảy ra thiệt hại, NSDLĐ sẽ áp dụng trách nhiệm vật chất trong việc sử dụng và bảo quản dụng cụ làm việc của NLĐ theo quy định của Pháp luật hiện hành, Quy định và Nội quy của Công ty.
A37: Điều 3: Quyền lợi, nghĩa vụ, trách nhiệm và cam kết của NLĐ
A38: - Quyền lợi:
A39: 1. Tiền lương (7):
A40: ="- Mức lương chính: "&IF($I$18="","…..",TEXT($I$18,"#,##0"))&" đồng/tháng." -> - Mức lương chính: ….. đồng/tháng.
A41: - Phụ cấp trách nhiệm: …đồng/tháng
A42: - Phụ cấp chức vụ: ….. đồng/tháng
A43: Tổng cộng: ……… đồng/tháng
A44: 2. Thời hạn trả lương: Được trả lương vào ngày cuối tháng.
...

Sheet HĐ LAO ĐỘNG LX
A1: CÔNG TY TNHH ĐẠI LỘ XANH | C1: CỘNG HÒA XÃ HỘI CHỦ NGHĨA VIỆT NAM | H1: BẢNG TRA CỨU (ẨN, hàng 2-15) - KHÔNG XÓA
A2: Số: 010625-01/HDLD/VP-CM | C2: Độc lập - Tự do - Hạnh phúc | H2: Mã NV | I2: =$M$2 -> 0 | K2: Nhập Mã NV để tự động điền hợp đồng: | N2: =IF($M$2="","",IFERROR("Đã chọn: "&$I$3&" - "&$I$4,"⚠ Không tìm thấy Mã NV trong sheet DS số TKNH"))
H3: Tên NV | I3: =IFERROR(INDEX('DS số TKNH'!$B:$B,MATCH($M$2,'DS số TKNH'!$D:$D,0)),"")
H4: Chức danh | I4: =IFERROR(INDEX('DS số TKNH'!$C:$C,MATCH($M$2,'DS số TKNH'!$D:$D,0)),"")
A5: ———o0o——— | H5: Ngày sinh | I5: =IFERROR(INDEX('DS số TKNH'!$E:$E,MATCH($M$2,'DS số TKNH'!$D:$D,0)),"")
H6: Giới tính | I6: =IFERROR(INDEX('DS số TKNH'!$F:$F,MATCH($M$2,'DS số TKNH'!$D:$D,0)),"")
A7: ….......... ngày …. tháng 0…. năm 2026 | H7: Số CCCD | I7: =IFERROR(INDEX('DS số TKNH'!$G:$G,MATCH($M$2,'DS số TKNH'!$D:$D,0)),"")
A8: HỢP ĐỒNG LAO ĐỘNG | H8: Ngày cấp CCCD | I8: =IFERROR(INDEX('DS số TKNH'!$H:$H,MATCH($M$2,'DS số TKNH'!$D:$D,0)),"")
A9: Chúng tôi, một bên là Ông: ……………………….Quốc tịch: Việt Nam | H9: Nơi cấp CCCD | I9: =IFERROR(INDEX('DS số TKNH'!$I:$I,MATCH($M$2,'DS số TKNH'!$D:$D,0)),"")
A10: Chức vụ: Giám Đốc | H10: Địa chỉ thường trú | I10: =IFERROR(INDEX('DS số TKNH'!$J:$J,MATCH($M$2,'DS số TKNH'!$D:$D,0)),"")
A11: Đại diện cho: CÔNG TY TNHH ……………………. | H11: Địa chỉ hiện tại | I11: =IFERROR(INDEX('DS số TKNH'!$K:$K,MATCH($M$2,'DS số TKNH'!$D:$D,0)),"")
A12: Trụ sở chính: …………………………… ……………. | H12: Số điện thoại | I12: =IFERROR(INDEX('DS số TKNH'!$L:$L,MATCH($M$2,'DS số TKNH'!$D:$D,0)),"")
A13: Điện thoại: ………………………….. | H13: Ngày vào làm | I13: =IFERROR(INDEX('DS số TKNH'!$M:$M,MATCH($M$2,'DS số TKNH'!$D:$D,0)),"")
A14: ="Và một bên là: Ông/Bà "&$I$3&" Quốc tịch: Việt Nam" -> Và một bên là: Ông/Bà Quốc tịch: Việt Nam | H14: Loại hợp đồng | I14: =IFERROR(INDEX('DS số TKNH'!$N:$N,MATCH($M$2,'DS số TKNH'!$D:$D,0)),"")
A15: ="Năm sinh: "&IF($I$5="","………………………………..",TEXT($I$5,"dd/mm/yyyy")) -> Năm sinh: ……………………………….. | H15: Mức lương | I15: =IFERROR(INDEX('Mức lương'!$D:$D,MATCH($I$3,'Mức lương'!$B:$B,0)),"")
A16: ="1. Địa chỉ thường trú: "&IF($I$10="","……………………………….",$I$10) -> 1. Địa chỉ thường trú: ……………………………….
A17: ="2. Địa chỉ hiện tại: "&IF($I$11="","…………………………….",$I$11) -> 2. Địa chỉ hiện tại: …………………………….
A18: ="3. Số CCCD: "&IF($I$7="","…………………………..",$I$7)&" Ngày cấp: "&IF($I$8="","………………………",TEXT($I$8,"dd/mm/yyyy")) -> 3. Số CCCD: ………………………….. Ngày cấp: ………………………
A19: ="4. Nơi cấp: "&IF($I$9="","Cục Cảnh sát QLHC về TTXH",$I$9) -> 4. Nơi cấp: Cục Cảnh sát QLHC về TTXH
A20: ="Số điện thoại: "&IF($I$12="","……………………………………….",$I$12) -> Số điện thoại: ……………………………………….
A21: Thỏa thuận ký kết hợp đồng lao động và cam kết làm đúng những điều khoản sau đây:
A22: Điều 1: Thời hạn và công việc hợp đồng
A23: ="Loại hợp đồng Lao động: Hợp đồng lao động "&IF($I$14="","không xác định thời hạn",LOWER($I$14)) -> Loại hợp đồng Lao động: Hợp đồng lao động không xác định thời hạn
A24: ="Từ ngày: "&IF($I$13="","01/06/2025",TEXT($I$13,"dd/mm/yyyy")) -> Từ ngày: 01/06/2025
A25: Địa điểm làm việc: ………………………….. …. ………. và (hoặc) một trong các địa điểm làm việc của Công ty khi có yêu cầu.
A26: ="Chức danh chuyên môn: "&IF($I$4="","Nhân viên lái xe",$I$4) -> Chức danh chuyên môn: Nhân viên lái xe
A27: Công việc phải làm: Chi tiết theo bảng Mô tả công việc kèm theo.
A28: Điều 2: Chế độ làm việc
A29: Thời giờ làm việc: 26 ngày / tháng
A30: Buổi sáng: 8h15 - 12h00
A31: Buổi chiều: Từ 13h30 - 17h45
A32: · Được cấp phát những dụng cụ làm việc gồm: Theo đặc thù ngành nghề và điều kiện công tác.
A33: Điều 3: Nghĩa vụ và quyền lợi của người lao động
A34: 1. Quyền lợi:
A35: Phương tiện đi lại, làm việc: Cá nhân tự túc
A36: ="Mức lương cơ bản: "&IF($I$15="","5.700.000",TEXT($I$15,"#,##0"))&" VND/ Tháng" -> Mức lương cơ bản: 5.700.000 VND/ Tháng
A37: các khoản phụ cấp, trợ cấp theo quy định và chức vụ tại công ty
A38: Hưởng thu nhập theo Quy chế Công ty
A39: Hình thức trả lương: Tiền mặt hoặc chuyển khoản.
A40: Thời gian trả lương được trả lương vào ngày: 10 hàng tháng (01 kỳ/tháng)
...

Sheet NỘI QUY LAO ĐỘNG
A1: CÔNG TY TNHH ĐẠI LỘ XANH
A13: NỘI QUY LAO ĐỘNG
A14: (Ban hành theo Quyết định số ……………../QĐ-… ngày ………………….)
A32: Phú Thọ, năm 2026
A33: MỤC LỤC
A34: CHƯƠNG I: NHỮNG QUY ĐỊNH CHUNG | F34: 1
A35: Điều 1. Định nghĩa | F35: 1
A36: Điều 2. Đối tượng áp dụng | F36: 1
A37: Điều 3. Áp dụng, sửa đổi và bổ sung | F37: 1
A38: Điều 4. Hiệu lực thi hành | F38: 1
A39: Điều 5. Giải thích từ ngữ và các từ viết tắt | F39: 2
A40: CHƯƠNG II: THỜI GIỜ LÀM VIỆC, THỜI GIAN NGHỈ NGƠI | F40: 3
A41: Điều 6. Thời gian làm việc và nghỉ ngơi | F41: 3
A42: Điều 7. Nghỉ giữa giờ | F42: 3
A43: Điều 8. Ngày nghỉ hưởng lương | F43: 3
A44: Điều 9. Nghỉ việc riêng không hưởng lương | F44: 4
A45: Điều 10. Quy định khi xin nghỉ | F45: 4
... A94: Điều 51. Giải quyết khiếu nại | F94: 37
A96: CHƯƠNG I
A97: NHỮNG QUY ĐỊNH CHUNG
A98: Điều 1. Định nghĩa
A99: Nội quy lao động là những quy định về kỷ luật lao động mà người lao động phải thực hiện khi làm việc tại Công ty ...; quy định việc xử lý đối với người lao động có hành vi vi phạm kỷ luật lao động; quy định trách nhiệm vật chất đối với người lao động vi phạm kỷ luật làm thiệt hại tài sản của Công ty.
A100: Điều 2. Đối tượng áp dụng
A101: Nội quy lao động áp dụng đối với tất cả mọi người lao động làm việc trong Công ty theo các hình thức và các loại hợp đồng lao động, kể cả người lao động trong thời gian thử việc, học nghề.
A102: Điều 3. Áp dụng, sửa đổi và bổ sung
A103: Mọi nội dung không có trong Nội quy lao động này được thực hiện đúng theo quy định hiện hành của Luật Lao động, Luật Bảo hiểm xã hội và các quy định khác của Nhà nước.
A104: Trong trường hợp Luật Lao động, Luật Bảo hiểm xã hội và các quy định khác của Nhà nước có thay đổi mà bản Nội quy lao động chưa chỉnh sửa thì thực hiện theo đúng những quy định đã thay đổi theo Luật.
A105: Tùy thuộc vào sự thay đổi chính sách của Công ty và pháp luật lao động, những điều khoản trong nội quy này có thể được sửa đổi, bổ sung tùy từng trường hợp. Công ty sẽ đăng ký những sửa đổi này tại Sở Lao động - Thương binh và Xã hội và thông báo cho tất cả người lao động được biết.
A106: Điều 4. Hiệu lực thi hành
A107: Nội quy lao động có hiệu lực thi hành sau 15 ngày kể từ ngày Sở Lao động - Thương binh và Xã hội thành phố Hà Nội nhận đầy đủ hồ sơ đăng ký Nội quy lao động mà không có thông báo sửa đổi, bổ sung.
A108: Điều 5. Giải thích từ ngữ
A109: STT | B109: Ký hiệu | D109: Nội dung
A110: 1 | B110: Người sử dụng lao động | D110: Công ty
B111: (Sau đây gọi tắt là Công ty)
A112: 2 | B112: Người lao động | D112: Toàn bộ người lao động đã ký hợp đồng với Công ty và hợp đồng còn hiệu lực.
B113: (Sau đây gọi tắt là CBNV)
A114: 3 | B114: Bộ phận (Sau đây gọi tắt là BP) | D114: Được hiểu là các Ban, Phòng, đơn vị trực thuộc Công ty.
A115: 4 | B115: Người quản lý trực tiếp | D115: Là người có quyền trực tiếp giao việc, quản lý, phân công công việc cho CBNV/ Bộ phận theo quy định của Công ty.
B116: (Sau đây gọi tắt là QLTT)
A117: 5 | B117: Nơi làm việc | D117: Là địa điểm, không gian mà CBNV phải có mặt để thực hiện nghĩa vụ lao động, theo thoả thuận giữa các bên hoặc theo yêu cầu của Công ty.
...

Sheet QUY CHẾ TIỀN LƯƠNG LX THEO DT
A1: CÔNG TY TNHH VẬN TẢI ĐẠI LỘ XANH | C1: CỘNG HÒA XÃ HỘI CHỦ NGHĨA VIỆT NAM
A2: Số: ....../QĐ-....... | C2: Độc lập - Tự do - Hạnh phúc
A3: ----------------- | C3: -----------------
C4: ......................, ngày ...... tháng ...... năm 2026
A5: QUY CHẾ TIỀN LƯƠNG
A6: (Áp dụng đối với tài xế xe container, tài xế xe tải và phụ xe)
A7: (Ban hành kèm theo Quyết định số ....../QĐ-....... ngày ...../....../2026 của Giám đốc Công ty ...................................)
A8: Chương I
A9: QUY ĐỊNH CHUNG
A10: Điều 1. Mục đích
A11: Quy chế này quy định thống nhất về nguyên tắc, phương pháp xây dựng thang lương, bảng lương và cách tính, chi trả lương đối với tài xế xe container, tài xế xe tải và phụ xe làm việc tại Công ty, nhằm:
A12: ● Bảo đảm quyền lợi hợp pháp của người lao động, tuân thủ Bộ luật Lao động năm 2019 và các văn bản hướng dẫn thi hành;
A13: ● Gắn thu nhập của tài xế, phụ xe với hiệu quả và doanh thu vận chuyển thực tế, khuyến khích tăng năng suất, tiết kiệm chi phí, bảo đảm an toàn giao thông;
A14: ● Làm căn cứ để giao kết hợp đồng lao động, đóng bảo hiểm xã hội, giải quyết các chế độ liên quan đến tiền lương.
A15: Điều 2. Phạm vi và đối tượng áp dụng
A16: Quy chế áp dụng đối với toàn bộ người lao động giữ các chức danh: tài xế xe container (xe đầu kéo, sơ mi rơ moóc), tài xế xe tải các loại và phụ xe đang làm việc theo hợp đồng lao động tại Công ty, không phân biệt loại hợp đồng, trừ trường hợp có thỏa thuận khác bằng văn bản.
... A23: Thang bảng lương tại Quy chế này được xây dựng trên cơ sở mức lương tối thiểu vùng quy định tại Nghị định số 293/2025/NĐ-CP ngày 10/11/2025 của Chính phủ, áp dụng từ ngày 01/01/2026, cụ thể như sau:
A24: Vùng | B24: Lương tối thiểu tháng (đồng/tháng) | C24: Lương tối thiểu giờ (đồng/giờ)
A25: Vùng I | B25: 4.960.000 | C25: 23.800
A26: Vùng II | B26: 4.410.000 | C26: 21.200
A27: Vùng III | B27: 3.860.000 | C27: 18.600
A28: Vùng IV | B28: 3.450.000 | C28: 16.600
A29: Ghi chú: Các mức lương cơ bản nêu tại Chương II của Quy chế này được xây dựng minh họa theo Vùng I. Công ty căn cứ địa bàn hoạt động thực tế (Vùng I, II, III hoặc IV) để điều chỉnh mức lương cơ bản cho phù hợp, bảo đảm không thấp hơn mức lương tối thiểu vùng tương ứng và không thấp hơn mức lương tối thiểu vùng cộng thêm ít nhất 7% đối với công việc đòi hỏi qua đào tạo nghề.
A30: Chương II
A31: THANG LƯƠNG, BẢNG LƯƠNG CƠ BẢN
A32: Điều 5. Thang lương tài xế xe container
A33: Bậc | B33: Điều kiện / thâm niên áp dụng | C33: Hệ số | D33: Lương cơ bản (đồng/tháng)
A34: 1 | B34: Mới tuyển dụng / dưới 1 năm kinh nghiệm lái xe đầu kéo container | C34: 2,20 | D34: 6.500.000
A35: 2 | B35: Từ đủ 1 năm đến dưới 3 năm kinh nghiệm | C35: 2,50 | D35: 7.500.000
A36: 3 | B36: Từ đủ 3 năm đến dưới 5 năm kinh nghiệm | C36: 2,80 | D36: 8.500.000
A37: 4 | B37: Từ đủ 5 năm trở lên, tay nghề cao, không vi phạm an toàn giao thông | C37: 3,10 | D37: 9.500.000
A38: Ghi chú: Việc xếp bậc lương căn cứ vào kinh nghiệm lái xe container, kết quả sát hạch tay nghề và quá trình chấp hành nội quy, an toàn giao thông của người lao động.
A39: Điều 6. Thang lương tài xế xe tải
A40: Loại xe (theo tải trọng) | B40: Bậc 1 (mới / dưới 1 năm) | C40: Bậc 2 (1 - 3 năm) | D40: Bậc 3 (trên 3 năm)
A41: Xe tải nhẹ (dưới 3,5 tấn) | B41: 5.300.000 | C41: 6.000.000 | D41: 6.700.000
A42: Xe tải trung (từ 3,5 đến 8 tấn) | B42: 6.000.000 | C42: 6.700.000 | D42: 7.400.000
A43: Xe tải nặng (trên 8 tấn) | B43: 6.700.000 | C43: 7.400.000 | D43: 8.200.000
A44: Ghi chú: Tải trọng xe được xác định theo Giấy chứng nhận kiểm định an toàn kỹ thuật và bảo vệ môi trường của phương tiện.
A45: Điều 7. Thang lương phụ xe
A46: Bậc | B46: Điều kiện / thâm niên áp dụng | C46: Lương cơ bản (đồng/tháng)
...

Sheet QUY CHẾ LƯƠNG LX THEO CHUYẾN
A1: CÔNG TY TNHH VẬN TẢI ĐẠI LỘ XANH | C1: CỘNG HÒA XÃ HỘI CHỦ NGHĨA VIỆT NAM
A2: Số: ....../QĐ-....... | C2: Độc lập - Tự do - Hạnh phúc
A3: ----------------- | C3: -----------------
C4: ......................, ngày ...... tháng ...... năm 2026
A5: QUY CHẾ TIỀN LƯƠNG
A6: (Áp dụng đối với tài xế xe container, xe fooc, xe mooc, xe tải và phụ xe)
A7: (Ban hành kèm theo Quyết định số ....../QĐ-....... ngày ...../....../2026 của Giám đốc Công ty ...................................)
A8: Chương I
A9: QUY ĐỊNH CHUNG
A10: Điều 1. Mục đích
A11: Quy chế này quy định thống nhất về nguyên tắc, phương pháp xây dựng thang lương, bảng lương và cách tính, chi trả lương đối với tài xế xe container, xe fooc, xe mooc, tài xế xe tải và phụ xe làm việc tại Công ty, nhằm:
A12: ● Bảo đảm quyền lợi hợp pháp của người lao động, tuân thủ Bộ luật Lao động năm 2019 và các văn bản hướng dẫn thi hành;
A13: ● Gắn thu nhập của tài xế, phụ xe với sản lượng vận chuyển thực tế (số chuyến, cự ly vận chuyển hoàn thành), khuyến khích tăng năng suất, tiết kiệm chi phí, bảo đảm an toàn giao thông;
A14: ● Làm căn cứ để giao kết hợp đồng lao động, đóng bảo hiểm xã hội, giải quyết các chế độ liên quan đến tiền lương.
A15: Điều 2. Phạm vi và đối tượng áp dụng
A16: Quy chế áp dụng đối với toàn bộ người lao động giữ các chức danh: tài xế xe container, tài xế xe đầu kéo rơ-moóc fooc, tài xế xe đầu kéo rơ-moóc (mooc), tài xế xe tải các loại và phụ xe đang làm việc theo hợp đồng lao động tại Công ty, không phân biệt loại hợp đồng, trừ trường hợp có thỏa thuận khác bằng văn bản.
... A24: Thang bảng lương tại Quy chế này được xây dựng trên cơ sở mức lương tối thiểu vùng quy định tại Nghị định số 293/2025/NĐ-CP ngày 10/11/2025 của Chính phủ, áp dụng từ ngày 01/01/2026, cụ thể như sau:
A25: Vùng | B25: Lương tối thiểu tháng (đồng/tháng) | C25: Lương tối thiểu giờ (đồng/giờ)
A26: Vùng I | B26: 4.960.000 | C26: 23.800
A27: Vùng II | B27: 4.410.000 | C27: 21.200
A28: Vùng III | B28: 3.860.000 | C28: 18.600
A29: Vùng IV | B29: 3.450.000 | C29: 16.600
A30: Ghi chú: Các mức lương cơ bản nêu tại Chương II của Quy chế này được xây dựng minh họa theo Vùng I. Công ty căn cứ địa bàn hoạt động thực tế (Vùng I, II, III hoặc IV) để điều chỉnh mức lương cơ bản cho phù hợp, bảo đảm không thấp hơn mức lương tối thiểu vùng tương ứng và không thấp hơn mức lương tối thiểu vùng cộng thêm ít nhất 7% đối với công việc đòi hỏi qua đào tạo nghề.
A31: Chương II
A32: THANG LƯƠNG, BẢNG LƯƠNG CƠ BẢN
A33: Điều 5. Thang lương nhóm tài xế xe đầu kéo (container, fooc, mooc)
A34: Loại xe đầu kéo | B34: Bậc 1 | C34: Bậc 2 | D34: Bậc 3 | E34: Bậc 4
B35: (dưới 1 năm) | C35: (1 - 3 năm) | D35: (3 - 5 năm) | E35: (trên 5 năm)
A36: Xe container | B36: 6.500.000 | C36: 7.500.000 | D36: 8.500.000 | E36: 9.500.000
A37: Xe fooc (rơ-moóc fooc) | B37: 6.700.000 | C37: 7.700.000 | D37: 8.700.000 | E37: 9.700.000
A38: Xe mooc (rơ-moóc sàn/thường) | B38: 6.600.000 | C38: 7.600.000 | D38: 8.600.000 | E38: 9.600.000
A39: Ghi chú: Việc xếp bậc lương căn cứ vào kinh nghiệm lái xe đầu kéo, kết quả sát hạch tay nghề và quá trình chấp hành nội quy, an toàn giao thông của người lao động. Mức lương cơ bản của xe fooc, xe mooc cao hơn xe container cùng bậc do yêu cầu kỹ năng buộc, chằng, gia cố hàng hóa phức tạp hơn.
A40: Điều 6. Thang lương tài xế xe tải
A41: Loại xe (theo tải trọng) | B41: Bậc 1 | C41: Bậc 2 | D41: Bậc 3
B42: (mới / dưới 1 năm) | C42: (1 - 3 năm) | D42: (trên 3 năm)
A43: Xe tải nhẹ (dưới 3,5 tấn) | B43: 5.300.000 | C43: 6.000.000 | D43: 6.700.000
A44: Xe tải trung (từ 3,5 đến 8 tấn) | B44: 6.000.000 | C44: 6.700.000 | D44: 7.400.000
A45: Xe tải nặng (trên 8 tấn) | B45: 6.700.000 | C45: 7.400.000 | D45: 8.200.000
A46: Ghi chú: Tải trọng xe được xác định theo Giấy chứng nhận kiểm định an toàn kỹ thuật và bảo vệ môi trường của phương tiện.
A47: Điều 7. Thang lương phụ xe
...

Sheet QUY CHẾ LƯƠNG VP
A1: CÔNG TY ................................... | C1: CỘNG HÒA XÃ HỘI CHỦ NGHĨA VIỆT NAM
A2: Số: ....../QĐ-....... | C2: Độc lập - Tự do - Hạnh phúc
A3: ----------------- | C3: -----------------
C4: ......................, ngày ...... tháng ...... năm 2026
A5: QUY CHẾ TIỀN LƯƠNG KHỐI VĂN PHÒNG
A6: (Áp dụng đối với Ban Giám đốc và các phòng: Kế toán, Chứng từ, Kinh doanh - CSKH, OPS, Điều vận, Nhân sự)
A7: (Ban hành kèm theo Quyết định số ....../QĐ-....... ngày ...../....../2026 của Giám đốc Công ty ...................................)
A8: Chương I
A9: QUY ĐỊNH CHUNG
A10: Điều 1. Mục đích
A11: Quy chế này quy định thống nhất về nguyên tắc, phương pháp xây dựng thang lương, bảng lương và cách tính, chi trả lương đối với Ban Giám đốc và cán bộ, nhân viên các phòng: Kế toán, Chứng từ, Kinh doanh - Chăm sóc khách hàng, OPS, Điều vận, Nhân sự của Công ty, nhằm:
A12: ● Bảo đảm quyền lợi hợp pháp của người lao động, tuân thủ Bộ luật Lao động năm 2019 và các văn bản hướng dẫn thi hành;
A13: ● Gắn thu nhập của cán bộ, nhân viên với hiệu quả, kết quả công việc và đóng góp thực tế của từng vị trí, từng phòng ban;
A14: ● Làm căn cứ để giao kết hợp đồng lao động, đóng bảo hiểm xã hội, giải quyết các chế độ liên quan đến tiền lương và xét nâng bậc lương.
A15: Điều 2. Phạm vi và đối tượng áp dụng
A16: Quy chế áp dụng đối với toàn bộ người lao động làm việc theo hợp đồng lao động tại các bộ phận sau của Công ty:
... A31: Thang bảng lương tại Quy chế này được xây dựng trên cơ sở mức lương tối thiểu vùng quy định tại Nghị định số 293/2025/NĐ-CP ngày 10/11/2025 của Chính phủ, áp dụng từ ngày 01/01/2026, cụ thể như sau:
A32: Vùng | B32: Lương tối thiểu tháng (đồng/tháng) | C32: Lương tối thiểu giờ (đồng/giờ)
A33: Vùng I | B33: 4.960.000 | C33: 23.800
A34: Vùng II | B34: 4.410.000 | C34: 21.200
A35: Vùng III | B35: 3.860.000 | C35: 18.600
A36: Vùng IV | B36: 3.450.000 | C36: 16.600
A37: Ghi chú: Các mức lương cơ bản nêu tại Chương II của Quy chế này được xây dựng minh họa theo Vùng I. Công ty căn cứ địa bàn hoạt động thực tế để điều chỉnh cho phù hợp, bảo đảm không thấp hơn mức lương tối thiểu vùng tương ứng và không thấp hơn mức lương tối thiểu vùng cộng thêm ít nhất 7% đối với công việc đòi hỏi qua đào tạo nghề.
A38: Chương II
A39: THANG LƯƠNG, BẢNG LƯƠNG THEO CHỨC DANH
A40: Điều 5. Nguyên tắc xếp bậc lương
A41: ● Đối với vị trí quản lý (Phó Giám đốc, Kế toán trưởng, Trưởng phòng): áp dụng 02 bậc lương. Bậc 1 áp dụng khi mới được bổ nhiệm hoặc có dưới 02 năm kinh nghiệm ở vị trí quản lý tương đương; Bậc 2 áp dụng khi đã đảm nhiệm vị trí từ đủ 02 năm trở lên, hoàn thành tốt nhiệm vụ được giao.
A42: ● Đối với vị trí chuyên viên, nhân viên: áp dụng 03 bậc lương. Bậc 1 áp dụng khi mới tuyển dụng hoặc có dưới 01 năm kinh nghiệm; Bậc 2 áp dụng khi có từ đủ 01 năm đến dưới 03 năm kinh nghiệm; Bậc 3 áp dụng khi có từ đủ 03 năm kinh nghiệm trở lên, thành thạo nghiệp vụ.
A43: ● Mức lương của Giám đốc/Tổng Giám đốc do chủ sở hữu/Hội đồng thành viên Công ty quyết định, thể hiện tại Hợp đồng lao động hoặc Quyết định bổ nhiệm, không áp dụng bậc lương chung tại Quy chế này.
A44: Điều 6. Thang lương Ban Giám đốc
A45: Chức danh | B45: Bậc 1 (mới bổ nhiệm / dưới 2 năm) | C45: Bậc 2 (từ 2 năm trở lên)
A46: Phó Giám đốc | B46: 22.000.000 | C46: 28.000.000
A47: Ghi chú: Mức lương của Giám đốc/Tổng Giám đốc theo Điều 5, không thấp hơn mức lương Bậc 2 của Phó Giám đốc.
A48: Điều 7. Thang lương Phòng Kế toán
A49: Chức danh | B49: Bậc 1 | C49: Bậc 2 | D49: Bậc 3
A50: Kế toán trưởng | B50: 15.000.000 | C50: 18.000.000 | D50: —
A51: Kế toán tổng hợp | B51: 9.000.000 | C51: 11.000.000 | D51: 13.000.000
A52: Kế toán công nợ | B52: 8.000.000 | C52: 9.500.000 | D52: 11.000.000
A53: Kế toán thanh toán - thủ quỹ | B53: 7.500.000 | C53: 9.000.000 | D53: 10.500.000
A54: Ghi chú: Kế toán trưởng phải đáp ứng tiêu chuẩn, điều kiện theo Luật Kế toán và được bổ nhiệm bằng quyết định riêng của Giám đốc.
...

Sheet TH_QUY CHẾ LƯƠNG (1 trang in)
A1: CÔNG TY ...................................
A2: BẢNG TỔNG HỢP QUY CHẾ TIỀN LƯƠNG
A3: (Trích yếu thang bảng lương, đơn giá, tỷ lệ hưởng - áp dụng từ 01/01/2026 theo Nghị định 293/2025/NĐ-CP về lương tối thiểu vùng)
A5: I. LƯƠNG LÁI XE THEO DOANH THU | E5: II. LƯƠNG LÁI XE THEO CHUYẾN | J5: III. LƯƠNG KHỐI VĂN PHÒNG
A6: 1. Lương cơ bản - Tài xế xe container | E6: 1. Lương cơ bản - Xe đầu kéo (cont/fooc/mooc) | J6: 1. Thang lương theo chức danh
A7: Bậc | B7: Thâm niên | C7: Lương CB | E7: Loại xe | F7: B1 | G7: B2 | H7: B3-4 | J7: Chức danh | K7: B1 | L7: B2 | M7: B3
A8: 1 | B8: Dưới 1 năm | C8: 6.500.000 | E8: Container | F8: 6.500.000 | G8: 7.500.000 | H8: 8.500-9.500.000 | J8: P.Giám đốc | K8: 22.000.000 | L8: 28.000.000 | M8: —
A9: 2 | B9: 1-3 năm | C9: 7.500.000 | E9: Fooc | F9: 6.700.000 | G9: 7.700.000 | H9: 8.700-9.700.000 | J9: Kế toán trưởng | K9: 15.000.000 | L9: 18.000.000 | M9: —
A10: 3 | B10: 3-5 năm | C10: 8.500.000 | E10: Mooc | F10: 6.600.000 | G10: 7.600.000 | H10: 8.600-9.600.000 | J10: Kế toán tổng hợp | K10: 9.000.000 | L10: 11.000.000 | M10: 13.000.000
A11: 4 | B11: Trên 5 năm | C11: 9.500.000 | E11: 2. Lương cơ bản - Xe tải / Phụ xe | J11: Kế toán công nợ | K11: 8.000.000 | L11: 9.500.000 | M11: 11.000.000
A12: 2. Lương cơ bản - Tài xế xe tải | E12: Loại xe | F12: B1 | G12: B2 | H12: B3 | J12: KT thanh toán-thủ quỹ | K12: 7.500.000 | L12: 9.000.000 | M12: 10.500.000
A13: Loại xe | B13: B1/B2 | C13: B3 | E13: Tải nhẹ (<3,5T) | F13: 5.300.000 | G13: 6.000.000 | H13: 6.700.000 | J13: TP Chứng từ | K13: 13.000.000 | L13: 16.000.000 | M13: —
A14: Nhẹ (<3,5T) | B14: 5.300.000-6.000.000 | C14: 6.700.000 | E14: Tải trung (3,5-8T) | F14: 6.000.000 | G14: 6.700.000 | H14: 7.400.000 | J14: NV chứng từ | K14: 7.500.000 | L14: 9.000.000 | M14: 10.500.000
A15: Trung (3,5-8T) | B15: 6.000.000-6.700.000 | C15: 7.400.000 | E15: Tải nặng (>8T) | F15: 6.700.000 | G15: 7.400.000 | H15: 8.200.000 | J15: TP Kinh doanh | K15: 15.000.000 | L15: 18.000.000 | M15: —
A16: Nặng (>8T) | B16: 6.700.000-7.400.000 | C16: 8.200.000 | E16: Phụ xe (B1/B2/B3) | F16: 4.500.000 | G16: 5.000.000 | H16: 5.500.000 | J16: NV Kinh doanh (Sales) | K16: 8.000.000 | L16: 9.000.000 | M16: 10.000.000
A17: 3. Lương cơ bản - Phụ xe | E17: 3. Đơn giá khoán theo cung đường (VD) | J17: NV CSKH | K17: 7.500.000 | L17: 8.500.000 | M17: 9.500.000
A18: Bậc | B18: Thâm niên | C18: Lương CB | E18: Cung đường | F18: Đầu kéo | G18: Xe tải | H18: Phụ xe | J18: TP OPS | K18: 14.000.000 | L18: 17.000.000 | M18: —
A19: 1 | B19: Mới/thử việc | C19: 4.500.000 | E19: Nội thành (<50km) | F19: 350.000 | G19: 250.000 | H19: 90.000 | J19: NV OPS | K19: 8.000.000 | L19: 9.500.000 | M19: 11.000.000
A20: 2 | B20: 1-3 năm | C20: 5.000.000 | E20: HCM-Cần Thơ/VT (150-200km) | F20: 1.100.000 | G20: 800.000 | H20: 250.000 | J20: TP Điều vận | K20: 13.000.000 | L20: 16.000.000 | M20: —
A21: 3 | B21: Trên 3 năm | C21: 5.500.000 | E21: HCM-Nha Trang/Q.Nhơn(400-600km) | F21: 2.600.000 | G21: 1.900.000 | H21: 500.000 | J21: NV Điều vận | K21: 7.500.000 | L21: 9.000.000 | M21: 10.500.000
A22: 4. Tỷ lệ (%) hưởng theo doanh thu (lũy tiến) | E22: HCM-Đà Nẵng (~950km) | F22: 4.800.000 | G22: 3.600.000 | H22: 900.000 | J22: TP Nhân sự | K22: 13.000.000 | L22: 16.000.000 | M22: —
A23: Đối tượng | B23: Mức doanh thu/tháng | C23: Tỷ lệ | E23: HCM-Hà Nội/HP (~1.700km) | F23: 8.500.000 | G23: 6.500.000 | H23: 1.600.000 | J23: CV Nhân sự-HC | K23: 7.500.000 | L23: 9.000.000 | M23: 10.500.000
